Workbook

Sheet 1_RFQ_DadosVendas
B1: LINK | C1: PROJECT | D1: COSTING_COMPANY | E1: SALES_GROUP | F1: ACCOUNT_MANAGER | G1: TECH_ENGINEER | H1: CUSTOMER | I1: REGION | J1: SALES | K1: STEP | M1: 2026 | N1: 2027 | O1: 2028 | P1: 2029 | Q1: 2030 | R1: Considerado na análise | S1: Observações
B2: RFQ102030 | C2: Peça A | D2: company | E2: group | F2: Jhon | G2: Mark | H2: CustomerA | I2: countryA | J2: 3906676 | K2: 30 | M2: 200000 | N2: 200000 | O2: 200000 | P2: 200000 | Q2: 200000 | S2: Obs. Vai até 2034
B3: RFQ405060 | C3: Peça B | D3: company | E3: group | F3: Jhon | G3: Mark | H3: CustomerB | I3: countryB | J3: 385140 | K3: 40 | O3: 150000 | P3: 150000 | Q3: 150000 | S3: Obs. Vai até 2034

Sheet IP_WC
D1: Req. machines | E1: Req. machines Strategy + RFQ | K1: Req. machines Strategy | Q1: Actual Oee (%) | R1: Req. capacity (h) Strategy | X1: Planned capacity (h) Strategy | Y1: Total capacity (h) Strategy | Z1: Quantity Strategy
A2: NECESSÁRIO INVESTIR? | B2: Name | C2: Description | D2: Actual machine | E2: 2025 | F2: 2026 | G2: 2027 | H2: 2028 | I2: 2029 | J2: 2030 | K2: 2025 | L2: 2026 | M2: 2027 | N2: 2028 | O2: 2029 | P2: 2030 | Q2: Standard Oee | R2: 2025 | S2: 2026 | T2: 2027 | U2: 2028 | V2: 2029 | W2: 2030 | X2: 2025 | Y2: 2025 | Z2: 2025 | AA2: 2026 | AB2: 2027 | AC2: 2028 | AD2: 2029 | AE2: 2030 | AF2: WC no RFQ | AG2: TESTE 2
B3: Total | D3: 91 | E3: 41.21 | F3: 36.53 | G3: 38.68 | H3: 40.35 | I3: 42.32 | J3: 42.76 | K3: 41.21 | L3: 36.53 | M3: 38.68 | N3: 40.35 | O3: 42.32 | P3: 42.76 | Q3: 70.57 | R3: 143876 | S3: 145235.81 | T3: 157105.09 | U3: 166653.23 | V3: 175697.4 | W3: 179794.39 | X3: 314991.12 | Y3: 388625.4 | Z3: 3.2411012e+08 | AA3: 250540752 | AB3: 264593491 | AC3: 278627700 | AD3: 292647843 | AE3: 308508022 | AG3: {=IF(AND(ISERR(FIND("sim",INDEX('existencia de wc'!K$2:K$193,MATCH(IP_WC!C3,'existencia de wc'!B$2:B$192,0))))=FALSE,SUMPRODUCT(('2_LN_DadosExportados'!V$2:V$314=IP_WC!C3)*('2_LN_DadosExportados'!A$2:A$314="X"))>0), "MOSTRAR","")}
A4: =IF(OR(E4>=D4,F4>=D4,G4>=D4,H4>=D4,I4>=D4,J4>=D4),"INVEST","OK") -> OK | B4: HOR-0150 | C4: WC - Fer Tor ROMI Multiplic30D | D4: 1 | E4: =IFERROR(((SUMIFS('2_LN_DadosExportados'!AM:AM,'2_LN_DadosExportados'!$V:$V,$C4,'2_LN_DadosExportados'!$A:$A,"X")+R4)/$X4)*$D4,"") -> 0 | F4: =IFERROR(((SUMIFS('2_LN_DadosExportados'!AN:AN,'2_LN_DadosExportados'!$V:$V,$C4,'2_LN_DadosExportados'!$A:$A,"X")+S4)/$X4)*$D4,"") -> 0 | G4: =IFERROR(((SUMIFS('2_LN_DadosExportados'!AO:AO,'2_LN_DadosExportados'!$V:$V,$C4,'2_LN_DadosExportados'!$A:$A,"X")+T4)/$X4)*$D4,"") -> 0 | H4: =IFERROR(((SUMIFS('2_LN_DadosExportados'!AP:AP,'2_LN_DadosExportados'!$V:$V,$C4,'2_LN_DadosExportados'!$A:$A,"X")+U4)/$X4)*$D4,"") -> 0 | I4: =IFERROR(((SUMIFS('2_LN_DadosExportados'!AQ:AQ,'2_LN_DadosExportados'!$V:$V,$C4,'2_LN_DadosExportados'!$A:$A,"X")+V4)/$X4)*$D4,"") -> 0 | J4: =IFERROR(((SUMIFS('2_LN_DadosExportados'!AR:AR,'2_LN_DadosExportados'!$V:$V,$C4,'2_LN_DadosExportados'!$A:$A,"X")+W4)/$X4)*$D4,"") -> 0 | K4: =IFERROR(R4/$X4*$D4,"") -> 0 | L4: =IFERROR(S4/$X4*$D4,"") -> 0 | M4: =IFERROR(T4/$X4*$D4,"") -> 0 | N4: =IFERROR(U4/$X4*$D4,"") -> 0 | O4: =IFERROR(V4/$X4*$D4,"") -> 0 | P4: =IFERROR(W4/$X4*$D4,"") -> 0 | Q4: 90 | R4: 0 | S4: 0 | T4: 0 | U4: 0 | V4: 0 | W4: 0 | X4: =Y4*(Q4/100) -> 5443.2 | Y4: =24*5.25*48*D4 -> 6048 | Z4: 0 | AA4: 0 | AB4: 0 | AC4: 0 | AD4: 0 | AE4: 0 | AF4: =IFERROR(VLOOKUP(C4,'2_LN_DadosExportados'!V:V,1,FALSE),"") | AG4: {=IF(AND(ISERR(FIND("sim",INDEX('existencia de wc'!K$2:K$193,MATCH(IP_WC!C4,'existencia de wc'!B$2:B$192,0))))=FALSE,SUMPRODUCT(('2_LN_DadosExportados'!V$2:V$314=IP_WC!C4)*('2_LN_DadosExportados'!A$2:A$314="X"))>0), "MOSTRAR","")}
A5: =IF(OR(E5>=D5,F5>=D5,G5>=D5,H5>=D5,I5>=D5,J5>=D5),"INVEST","OK") -> OK | B5: HOR-0160 | C5: WC - Fer Torno Mazak Integrex | D5: 1 | E5: =IFERROR(((SUMIFS('2_LN_DadosExportados'!AM:AM,'2_LN_DadosExportados'!$V:$V,$C5,'2_LN_DadosExportados'!$A:$A,"X")+R5)/$X5)*$D5,"") -> 0 | F5: =IFERROR(((SUMIFS('2_LN_DadosExportados'!AN:AN,'2_LN_DadosExportados'!$V:$V,$C5,'2_LN_DadosExportados'!$A:$A,"X")+S5)/$X5)*$D5,"") -> 0 | G5: =IFERROR(((SUMIFS('2_LN_DadosExportados'!AO:AO,'2_LN_DadosExportados'!$V:$V,$C5,'2_LN_DadosExportados'!$A:$A,"X")+T5)/$X5)*$D5,"") -> 0 | H5: =IFERROR(((SUMIFS('2_LN_DadosExportados'!AP:AP,'2_LN_DadosExportados'!$V:$V,$C5,'2_LN_DadosExportados'!$A:$A,"X")+U5)/$X5)*$D5,"") -> 0 | I5: =IFERROR(((SUMIFS('2_LN_DadosExportados'!AQ:AQ,'2_LN_DadosExportados'!$V:$V,$C5,'2_LN_DadosExportados'!$A:$A,"X")+V5)/$X5)*$D5,"") -> 0 | J5: =IFERROR(((SUMIFS('2_LN_DadosExportados'!AR:AR,'2_LN_DadosExportados'!$V:$V,$C5,'2_LN_DadosExportados'!$A:$A,"X")+W5)/$X5)*$D5,"") -> 0 | K5: =IFERROR(R5/$X5*$D5,"") -> 0 | L5: =IFERROR(S5/$X5*$D5,"") -> 0 | M5: =IFERROR(T5/$X5*$D5,"") -> 0 | N5: =IFERROR(U5/$X5*$D5,"") -> 0 | O5: =IFERROR(V5/$X5*$D5,"") -> 0 | P5: =IFERROR(W5/$X5*$D5,"") -> 0 | Q5: 90 | R5: 0 | S5: 0 | T5: 0 | U5: 0 | V5: 0 | W5: 0 | X5: =Y5*(Q5/100) -> 5443.2 | Y5: =24*5.25*48*D5 -> 6048 | Z5: 0 | AA5: 0 | AB5: 0 | AC5: 0 | AD5: 0 | AE5: 0 | AF5: =IFERROR(VLOOKUP(C5,'2_LN_DadosExportados'!V:V,1,FALSE),"") | AG5: {=IF(AND(ISERR(FIND("sim",INDEX('existencia de wc'!K$2:K$193,MATCH(IP_WC!C5,'existencia de wc'!B$2:B$192,0))))=FALSE,SUMPRODUCT(('2_LN_DadosExportados'!V$2:V$314=IP_WC!C5)*('2_LN_DadosExportados'!A$2:A$314="X"))>0), "MOSTRAR","")}
A6: =IF(OR(E6>=D6,F6>=D6,G6>=D6,H6>=D6,I6>=D6,J6>=D6),"INVEST","OK") -> OK | B6: HOR-0201 | C6: WC - Fer Fresadora | D6: 1 | E6: =IFERROR(((SUMIFS('2_LN_DadosExportados'!AM:AM,'2_LN_DadosExportados'!$V:$V,$C6,'2_LN_DadosExportados'!$A:$A,"X")+R6)/$X6)*$D6,"") -> 0 | F6: =IFERROR(((SUMIFS('2_LN_DadosExportados'!AN:AN,'2_LN_DadosExportados'!$V:$V,$C6,'2_LN_DadosExportados'!$A:$A,"X")+S6)/$X6)*$D6,"") -> 0 | G6: =IFERROR(((SUMIFS('2_LN_DadosExportados'!AO:AO,'2_LN_DadosExportados'!$V:$V,$C6,'2_LN_DadosExportados'!$A:$A,"X")+T6)/$X6)*$D6,"") -> 0 | H6: =IFERROR(((SUMIFS('2_LN_DadosExportados'!AP:AP,'2_LN_DadosExportados'!$V:$V,$C6,'2_LN_DadosExportados'!$A:$A,"X")+U6)/$X6)*$D6,"") -> 0 | I6: =IFERROR(((SUMIFS('2_LN_DadosExportados'!AQ:AQ,'2_LN_DadosExportados'!$V:$V,$C6,'2_LN_DadosExportados'!$A:$A,"X")+V6)/$X6)*$D6,"") -> 0 | J6: =IFERROR(((SUMIFS('2_LN_DadosExportados'!AR:AR,'2_LN_DadosExportados'!$V:$V,$C6,'2_LN_DadosExportados'!$A:$A,"X")+W6)/$X6)*$D6,"") -> 0 | K6: =IFERROR(R6/$X6*$D6,"") -> 0 | L6: =IFERROR(S6/$X6*$D6,"") -> 0 | M6: =IFERROR(T6/$X6*$D6,"") -> 0 | N6: =IFERROR(U6/$X6*$D6,"") -> 0 | O6: =IFERROR(V6/$X6*$D6,"") -> 0 | P6: =IFERROR(W6/$X6*$D6,"") -> 0 | Q6: 90 | R6: 0 | S6: 0 | T6: 0 | U6: 0 | V6: 0 | W6: 0 | X6: =Y6*(Q6/100) -> 5443.2 | Y6: =24*5.25*48*D6 -> 6048 | Z6: 0 | AA6: 0 | AB6: 0 | AC6: 0 | AD6: 0 | AE6: 0 | AF6: =IFERROR(VLOOKUP(C6,'2_LN_DadosExportados'!V:V,1,FALSE),"") | AG6: {=IF(AND(ISERR(FIND("sim",INDEX('existencia de wc'!K$2:K$193,MATCH(IP_WC!C6,'existencia de wc'!B$2:B$192,0))))=FALSE,SUMPRODUCT(('2_LN_DadosExportados'!V$2:V$314=IP_WC!C6)*('2_LN_DadosExportados'!A$2:A$314="X"))>0), "MOSTRAR","")}
A7: =IF(OR(E7>=D7,F7>=D7,G7>=D7,H7>=D7,I7>=D7,J7>=D7),"INVEST","OK") -> OK | B7: HOR-0300 | C7: WC - Fer Eletro Fio Challenge | D7: 1 | E7: =IFERROR(((SUMIFS('2_LN_DadosExportados'!AM:AM,'2_LN_DadosExportados'!$V:$V,$C7,'2_LN_DadosExportados'!$A:$A,"X")+R7)/$X7)*$D7,"") -> 0 | F7: =IFERROR(((SUMIFS('2_LN_DadosExportados'!AN:AN,'2_LN_DadosExportados'!$V:$V,$C7,'2_LN_DadosExportados'!$A:$A,"X")+S7)/$X7)*$D7,"") -> 0 | G7: =IFERROR(((SUMIFS('2_LN_DadosExportados'!AO:AO,'2_LN_DadosExportados'!$V:$V,$C7,'2_LN_DadosExportados'!$A:$A,"X")+T7)/$X7)*$D7,"") -> 0 | H7: =IFERROR(((SUMIFS('2_LN_DadosExportados'!AP:AP,'2_LN_DadosExportados'!$V:$V,$C7,'2_LN_DadosExportados'!$A:$A,"X")+U7)/$X7)*$D7,"") -> 0 | I7: =IFERROR(((SUMIFS('2_LN_DadosExportados'!AQ:AQ,'2_LN_DadosExportados'!$V:$V,$C7,'2_LN_DadosExportados'!$A:$A,"X")+V7)/$X7)*$D7,"") -> 0 | J7: =IFERROR(((SUMIFS('2_LN_DadosExportados'!AR:AR,'2_LN_DadosExportados'!$V:$V,$C7,'2_LN_DadosExportados'!$A:$A,"X")+W7)/$X7)*$D7,"") -> 0 | K7: =IFERROR(R7/$X7*$D7,"") -> 0 | L7: =IFERROR(S7/$X7*$D7,"") -> 0 | M7: =IFERROR(T7/$X7*$D7,"") -> 0 | N7: =IFERROR(U7/$X7*$D7,"") -> 0 | O7: =IFERROR(V7/$X7*$D7,"") -> 0 | P7: =IFERROR(W7/$X7*$D7,"") -> 0 | Q7: 90 | R7: 0 | S7: 0 | T7: 0 | U7: 0 | V7: 0 | W7: 0 | X7: =Y7*(Q7/100) -> 5443.2 | Y7: =24*5.25*48*D7 -> 6048 | Z7: 0 | AA7: 0 | AB7: 0 | AC7: 0 | AD7: 0 | AE7: 0 | AF7: =IFERROR(VLOOKUP(C7,'2_LN_DadosExportados'!V:V,1,FALSE),"") | AG7: {=IF(AND(ISERR(FIND("sim",INDEX('existencia de wc'!K$2:K$193,MATCH(IP_WC!C7,'existencia de wc'!B$2:B$192,0))))=FALSE,SUMPRODUCT(('2_LN_DadosExportados'!V$2:V$314=IP_WC!C7)*('2_LN_DadosExportados'!A$2:A$314="X"))>0), "MOSTRAR","")}
A8: =IF(OR(E8>=D8,F8>=D8,G8>=D8,H8>=D8,I8>=D8,J8>=D8),"INVEST","OK") -> OK | B8: HOR-0310 | C8: WC - Fer Eletro Furo Rápido | D8: 1 | E8: =IFERROR(((SUMIFS('2_LN_DadosExportados'!AM:AM,'2_LN_DadosExportados'!$V:$V,$C8,'2_LN_DadosExportados'!$A:$A,"X")+R8)/$X8)*$D8,"") -> 0 | F8: =IFERROR(((SUMIFS('2_LN_DadosExportados'!AN:AN,'2_LN_DadosExportados'!$V:$V,$C8,'2_LN_DadosExportados'!$A:$A,"X")+S8)/$X8)*$D8,"") -> 0 | G8: =IFERROR(((SUMIFS('2_LN_DadosExportados'!AO:AO,'2_LN_DadosExportados'!$V:$V,$C8,'2_LN_DadosExportados'!$A:$A,"X")+T8)/$X8)*$D8,"") -> 0 | H8: =IFERROR(((SUMIFS('2_LN_DadosExportados'!AP:AP,'2_LN_DadosExportados'!$V:$V,$C8,'2_LN_DadosExportados'!$A:$A,"X")+U8)/$X8)*$D8,"") -> 0 | I8: =IFERROR(((SUMIFS('2_LN_DadosExportados'!AQ:AQ,'2_LN_DadosExportados'!$V:$V,$C8,'2_LN_DadosExportados'!$A:$A,"X")+V8)/$X8)*$D8,"") -> 0 | J8: =IFERROR(((SUMIFS('2_LN_DadosExportados'!AR:AR,'2_LN_DadosExportados'!$V:$V,$C8,'2_LN_DadosExportados'!$A:$A,"X")+W8)/$X8)*$D8,"") -> 0 | K8: =IFERROR(R8/$X8*$D8,"") -> 0 | L8: =IFERROR(S8/$X8*$D8,"") -> 0 | M8: =IFERROR(T8/$X8*$D8,"") -> 0 | N8: =IFERROR(U8/$X8*$D8,"") -> 0 | O8: =IFERROR(V8/$X8*$D8,"") -> 0 | P8: =IFERROR(W8/$X8*$D8,"") -> 0 | Q8: 90 | R8: 0 | S8: 0 | T8: 0 | U8: 0 | V8: 0 | W8: 0 | X8: =Y8*(Q8/100) -> 5443.2 | Y8: =24*5.25*48*D8 -> 6048 | Z8: 0 | AA8: 0 | AB8: 0 | AC8: 0 | AD8: 0 | AE8: 0 | AF8: =IFERROR(VLOOKUP(C8,'2_LN_DadosExportados'!V:V,1,FALSE),"") | AG8: {=IF(AND(ISERR(FIND("sim",INDEX('existencia de wc'!K$2:K$193,MATCH(IP_WC!C8,'existencia de wc'!B$2:B$192,0))))=FALSE,SUMPRODUCT(('2_LN_DadosExportados'!V$2:V$314=IP_WC!C8)*('2_LN_DadosExportados'!A$2:A$314="X"))>0), "MOSTRAR","")}
A9: =IF(OR(E9>=D9,F9>=D9,G9>=D9,H9>=D9,I9>=D9,J9>=D9),"INVEST","OK") -> OK | B9: HOR-0311 | C9: WC - Fer Penet Form P600 | D9: 1 | E9: =IFERROR(((SUMIFS('2_LN_DadosExportados'!AM:AM,'2_LN_DadosExportados'!$V:$V,$C9,'2_LN_DadosExportados'!$A:$A,"X")+R9)/$X9)*$D9,"") -> 0 | F9: =IFERROR(((SUMIFS('2_LN_DadosExportados'!AN:AN,'2_LN_DadosExportados'!$V:$V,$C9,'2_LN_DadosExportados'!$A:$A,"X")+S9)/$X9)*$D9,"") -> 0 | G9: =IFERROR(((SUMIFS('2_LN_DadosExportados'!AO:AO,'2_LN_DadosExportados'!$V:$V,$C9,'2_LN_DadosExportados'!$A:$A,"X")+T9)/$X9)*$D9,"") -> 0 | H9: =IFERROR(((SUMIFS('2_LN_DadosExportados'!AP:AP,'2_LN_DadosExportados'!$V:$V,$C9,'2_LN_DadosExportados'!$A:$A,"X")+U9)/$X9)*$D9,"") -> 0 | I9: =IFERROR(((SUMIFS('2_LN_DadosExportados'!AQ:AQ,'2_LN_DadosExportados'!$V:$V,$C9,'2_LN_DadosExportados'!$A:$A,"X")+V9)/$X9)*$D9,"") -> 0 | J9: =IFERROR(((SUMIFS('2_LN_DadosExportados'!AR:AR,'2_LN_DadosExportados'!$V:$V,$C9,'2_LN_DadosExportados'!$A:$A,"X")+W9)/$X9)*$D9,"") -> 0 | K9: =IFERROR(R9/$X9*$D9,"") -> 0 | L9: =IFERROR(S9/$X9*$D9,"") -> 0 | M9: =IFERROR(T9/$X9*$D9,"") -> 0 | N9: =IFERROR(U9/$X9*$D9,"") -> 0 | O9: =IFERROR(V9/$X9*$D9,"") -> 0 | P9: =IFERROR(W9/$X9*$D9,"") -> 0 | Q9: 90 | R9: 0 | S9: 0 | T9: 0 | U9: 0 | V9: 0 | W9: 0 | X9: =Y9*(Q9/100) -> 5443.2 | Y9: =24*5.25*48*D9 -> 6048 | Z9: 0 | AA9: 0 | AB9: 0 | AC9: 0 | AD9: 0 | AE9: 0 | AF9: =IFERROR(VLOOKUP(C9,'2_LN_DadosExportados'!V:V,1,FALSE),"") | AG9: {=IF(AND(ISERR(FIND("sim",INDEX('existencia de wc'!K$2:K$193,MATCH(IP_WC!C9,'existencia de wc'!B$2:B$192,0))))=FALSE,SUMPRODUCT(('2_LN_DadosExportados'!V$2:V$314=IP_WC!C9)*('2_LN_DadosExportados'!A$2:A$314="X"))>0), "MOSTRAR","")}
A10: =IF(OR(E10>=D10,F10>=D10,G10>=D10,H10>=D10,I10>=D10,J10>=D10),"INVEST","OK") -> OK | B10: HOR-0313 | C10: WC - Fer Penetração Hiper Sp | D10: 1 | E10: =IFERROR(((SUMIFS('2_LN_DadosExportados'!AM:AM,'2_LN_DadosExportados'!$V:$V,$C10,'2_LN_DadosExportados'!$A:$A,"X")+R10)/$X10)*$D10,"") -> 0 | F10: =IFERROR(((SUMIFS('2_LN_DadosExportados'!AN:AN,'2_LN_DadosExportados'!$V:$V,$C10,'2_LN_DadosExportados'!$A:$A,"X")+S10)/$X10)*$D10,"") -> 0 | G10: =IFERROR(((SUMIFS('2_LN_DadosExportados'!AO:AO,'2_LN_DadosExportados'!$V:$V,$C10,'2_LN_DadosExportados'!$A:$A,"X")+T10)/$X10)*$D10,"") -> 0 | H10: =IFERROR(((SUMIFS('2_LN_DadosExportados'!AP:AP,'2_LN_DadosExportados'!$V:$V,$C10,'2_LN_DadosExportados'!$A:$A,"X")+U10)/$X10)*$D10,"") -> 0 | I10: =IFERROR(((SUMIFS('2_LN_DadosExportados'!AQ:AQ,'2_LN_DadosExportados'!$V:$V,$C10,'2_LN_DadosExportados'!$A:$A,"X")+V10)/$X10)*$D10,"") -> 0 | J10: =IFERROR(((SUMIFS('2_LN_DadosExportados'!AR:AR,'2_LN_DadosExportados'!$V:$V,$C10,'2_LN_DadosExportados'!$A:$A,"X")+W10)/$X10)*$D10,"") -> 0 | K10: =IFERROR(R10/$X10*$D10,"") -> 0 | L10: =IFERROR(S10/$X10*$D10,"") -> 0 | M10: =IFERROR(T10/$X10*$D10,"") -> 0 | N10: =IFERROR(U10/$X10*$D10,"") -> 0 | O10: =IFERROR(V10/$X10*$D10,"") -> 0 | P10: =IFERROR(W10/$X10*$D10,"") -> 0 | Q10: 90 | R10: 0 | S10: 0 | T10: 0 | U10: 0 | V10: 0 | W10: 0 | X10: =Y10*(Q10/100) -> 5443.2 | Y10: =24*5.25*48*D10 -> 6048 | Z10: 0 | AA10: 0 | AB10: 0 | AC10: 0 | AD10: 0 | AE10: 0 | AF10: =IFERROR(VLOOKUP(C10,'2_LN_DadosExportados'!V:V,1,FALSE),"") | AG10: {=IF(AND(ISERR(FIND("sim",INDEX('existencia de wc'!K$2:K$193,MATCH(IP_WC!C10,'existencia de wc'!B$2:B$192,0))))=FALSE,SUMPRODUCT(('2_LN_DadosExportados'!V$2:V$314=IP_WC!C10)*('2_LN_DadosExportados'!A$2:A$314="X"))>0), "MOSTRAR","")}
A11: =IF(OR(E11>=D11,F11>=D11,G11>=D11,H11>=D11,I11>=D11,J11>=D11),"INVEST","OK") -> OK | B11: HOR-0314 | C11: WC - Fer Penetração Form 20 | D11: 1 | E11: =IFERROR(((SUMIFS('2_LN_DadosExportados'!AM:AM,'2_LN_DadosExportados'!$V:$V,$C11,'2_LN_DadosExportados'!$A:$A,"X")+R11)/$X11)*$D11,"") -> 0 | F11: =IFERROR(((SUMIFS('2_LN_DadosExportados'!AN:AN,'2_LN_DadosExportados'!$V:$V,$C11,'2_LN_DadosExportados'!$A:$A,"X")+S11)/$X11)*$D11,"") -> 0 | G11: =IFERROR(((SUMIFS('2_LN_DadosExportados'!AO:AO,'2_LN_DadosExportados'!$V:$V,$C11,'2_LN_DadosExportados'!$A:$A,"X")+T11)/$X11)*$D11,"") -> 0 | H11: =IFERROR(((SUMIFS('2_LN_DadosExportados'!AP:AP,'2_LN_DadosExportados'!$V:$V,$C11,'2_LN_DadosExportados'!$A:$A,"X")+U11)/$X11)*$D11,"") -> 0 | I11: =IFERROR(((SUMIFS('2_LN_DadosExportados'!AQ:AQ,'2_LN_DadosExportados'!$V:$V,$C11,'2_LN_DadosExportados'!$A:$A,"X")+V11)/$X11)*$D11,"") -> 0 | J11: =IFERROR(((SUMIFS('2_LN_DadosExportados'!AR:AR,'2_LN_DadosExportados'!$V:$V,$C11,'2_LN_DadosExportados'!$A:$A,"X")+W11)/$X11)*$D11,"") -> 0 | K11: =IFERROR(R11/$X11*$D11,"") -> 0 | L11: =IFERROR(S11/$X11*$D11,"") -> 0 | M11: =IFERROR(T11/$X11*$D11,"") -> 0 | N11: =IFERROR(U11/$X11*$D11,"") -> 0 | O11: =IFERROR(V11/$X11*$D11,"") -> 0 | P11: =IFERROR(W11/$X11*$D11,"") -> 0 | Q11: 90 | R11: 0 | S11: 0 | T11: 0 | U11: 0 | V11: 0 | W11: 0 | X11: =Y11*(Q11/100) -> 5443.2 | Y11: =24*5.25*48*D11 -> 6048 | Z11: 0 | AA11: 0 | AB11: 0 | AC11: 0 | AD11: 0 | AE11: 0 | AF11: =IFERROR(VLOOKUP(C11,'2_LN_DadosExportados'!V:V,1,FALSE),"") | AG11: {=IF(AND(ISERR(FIND("sim",INDEX('existencia de wc'!K$2:K$193,MATCH(IP_WC!C11,'existencia de wc'!B$2:B$192,0))))=FALSE,SUMPRODUCT(('2_LN_DadosExportados'!V$2:V$314=IP_WC!C11)*('2_LN_DadosExportados'!A$2:A$314="X"))>0), "MOSTRAR","")}
A12: =IF(OR(E12>=D12,F12>=D12,G12>=D12,H12>=D12,I12>=D12,J12>=D12),"INVEST","OK") -> OK | B12: HOR-0315 | C12: WC - Fer Fio Progress | D12: 1 | E12: =IFERROR(((SUMIFS('2_LN_DadosExportados'!AM:AM,'2_LN_DadosExportados'!$V:$V,$C12,'2_LN_DadosExportados'!$A:$A,"X")+R12)/$X12)*$D12,"") -> 0 | F12: =IFERROR(((SUMIFS('2_LN_DadosExportados'!AN:AN,'2_LN_DadosExportados'!$V:$V,$C12,'2_LN_DadosExportados'!$A:$A,"X")+S12)/$X12)*$D12,"") -> 0 | G12: =IFERROR(((SUMIFS('2_LN_DadosExportados'!AO:AO,'2_LN_DadosExportados'!$V:$V,$C12,'2_LN_DadosExportados'!$A:$A,"X")+T12)/$X12)*$D12,"") -> 0 | H12: =IFERROR(((SUMIFS('2_LN_DadosExportados'!AP:AP,'2_LN_DadosExportados'!$V:$V,$C12,'2_LN_DadosExportados'!$A:$A,"X")+U12)/$X12)*$D12,"") -> 0 | I12: =IFERROR(((SUMIFS('2_LN_DadosExportados'!AQ:AQ,'2_LN_DadosExportados'!$V:$V,$C12,'2_LN_DadosExportados'!$A:$A,"X")+V12)/$X12)*$D12,"") -> 0 | J12: =IFERROR(((SUMIFS('2_LN_DadosExportados'!AR:AR,'2_LN_DadosExportados'!$V:$V,$C12,'2_LN_DadosExportados'!$A:$A,"X")+W12)/$X12)*$D12,"") -> 0 | K12: =IFERROR(R12/$X12*$D12,"") -> 0 | L12: =IFERROR(S12/$X12*$D12,"") -> 0 | M12: =IFERROR(T12/$X12*$D12,"") -> 0 | N12: =IFERROR(U12/$X12*$D12,"") -> 0 | O12: =IFERROR(V12/$X12*$D12,"") -> 0 | P12: =IFERROR(W12/$X12*$D12,"") -> 0 | Q12: 90 | R12: 0 | S12: 0 | T12: 0 | U12: 0 | V12: 0 | W12: 0 | X12: =Y12*(Q12/100) -> 5443.2 | Y12: =24*5.25*48*D12 -> 6048 | Z12: 0 | AA12: 0 | AB12: 0 | AC12: 0 | AD12: 0 | AE12: 0 | AF12: =IFERROR(VLOOKUP(C12,'2_LN_DadosExportados'!V:V,1,FALSE),"") | AG12: {=IF(AND(ISERR(FIND("sim",INDEX('existencia de wc'!K$2:K$193,MATCH(IP_WC!C12,'existencia de wc'!B$2:B$192,0))))=FALSE,SUMPRODUCT(('2_LN_DadosExportados'!V$2:V$314=IP_WC!C12)*('2_LN_DadosExportados'!A$2:A$314="X"))>0), "MOSTRAR","")}
A13: =IF(OR(E13>=D13,F13>=D13,G13>=D13,H13>=D13,I13>=D13,J13>=D13),"INVEST","OK") -> OK | B13: HOR-0350 | C13: WC - Fer Bancada/Polimento | D13: 2 | E13: =IFERROR(((SUMIFS('2_LN_DadosExportados'!AM:AM,'2_LN_DadosExportados'!$V:$V,$C13,'2_LN_DadosExportados'!$A:$A,"X")+R13)/$X13)*$D13,"") -> 0 | F13: =IFERROR(((SUMIFS('2_LN_DadosExportados'!AN:AN,'2_LN_DadosExportados'!$V:$V,$C13,'2_LN_DadosExportados'!$A:$A,"X")+S13)/$X13)*$D13,"") -> 0 | G13: =IFERROR(((SUMIFS('2_LN_DadosExportados'!AO:AO,'2_LN_DadosExportados'!$V:$V,$C13,'2_LN_DadosExportados'!$A:$A,"X")+T13)/$X13)*$D13,"") -> 0 | H13: =IFERROR(((SUMIFS('2_LN_DadosExportados'!AP:AP,'2_LN_DadosExportados'!$V:$V,$C13,'2_LN_DadosExportados'!$A:$A,"X")+U13)/$X13)*$D13,"") -> 0 | I13: =IFERROR(((SUMIFS('2_LN_DadosExportados'!AQ:AQ,'2_LN_DadosExportados'!$V:$V,$C13,'2_LN_DadosExportados'!$A:$A,"X")+V13)/$X13)*$D13,"") -> 0 | J13: =IFERROR(((SUMIFS('2_LN_DadosExportados'!AR:AR,'2_LN_DadosExportados'!$V:$V,$C13,'2_LN_DadosExportados'!$A:$A,"X")+W13)/$X13)*$D13,"") -> 0 | K13: =IFERROR(R13/$X13*$D13,"") -> 0 | L13: =IFERROR(S13/$X13*$D13,"") -> 0 | M13: =IFERROR(T13/$X13*$D13,"") -> 0 | N13: =IFERROR(U13/$X13*$D13,"") -> 0 | O13: =IFERROR(V13/$X13*$D13,"") -> 0 | P13: =IFERROR(W13/$X13*$D13,"") -> 0 | Q13: 90 | R13: 0 | S13: 0 | T13: 0 | U13: 0 | V13: 0 | W13: 0 | X13: =Y13*(Q13/100) -> 10886.4 | Y13: =24*5.25*48*D13 -> 12096 | Z13: 0 | AA13: 0 | AB13: 0 | AC13: 0 | AD13: 0 | AE13: 0 | AF13: =IFERROR(VLOOKUP(C13,'2_LN_DadosExportados'!V:V,1,FALSE),"") | AG13: {=IF(AND(ISERR(FIND("sim",INDEX('existencia de wc'!K$2:K$193,MATCH(IP_WC!C13,'existencia de wc'!B$2:B$192,0))))=FALSE,SUMPRODUCT(('2_LN_DadosExportados'!V$2:V$314=IP_WC!C13)*('2_LN_DadosExportados'!A$2:A$314="X"))>0), "MOSTRAR","")}
A14: =IF(OR(E14>=D14,F14>=D14,G14>=D14,H14>=D14,I14>=D14,J14>=D14),"INVEST","OK") -> OK | B14: HOR-0380 | C14: WC - Fer Forno Engefor | D14: 2 | E14: =IFERROR(((SUMIFS('2_LN_DadosExportados'!AM:AM,'2_LN_DadosExportados'!$V:$V,$C14,'2_LN_DadosExportados'!$A:$A,"X")+R14)/$X14)*$D14,"") -> 0 | F14: =IFERROR(((SUMIFS('2_LN_DadosExportados'!AN:AN,'2_LN_DadosExportados'!$V:$V,$C14,'2_LN_DadosExportados'!$A:$A,"X")+S14)/$X14)*$D14,"") -> 0 | G14: =IFERROR(((SUMIFS('2_LN_DadosExportados'!AO:AO,'2_LN_DadosExportados'!$V:$V,$C14,'2_LN_DadosExportados'!$A:$A,"X")+T14)/$X14)*$D14,"") -> 0 | H14: =IFERROR(((SUMIFS('2_LN_DadosExportados'!AP:AP,'2_LN_DadosExportados'!$V:$V,$C14,'2_LN_DadosExportados'!$A:$A,"X")+U14)/$X14)*$D14,"") -> 0 | I14: =IFERROR(((SUMIFS('2_LN_DadosExportados'!AQ:AQ,'2_LN_DadosExportados'!$V:$V,$C14,'2_LN_DadosExportados'!$A:$A,"X")+V14)/$X14)*$D14,"") -> 0 | J14: =IFERROR(((SUMIFS('2_LN_DadosExportados'!AR:AR,'2_LN_DadosExportados'!$V:$V,$C14,'2_LN_DadosExportados'!$A:$A,"X")+W14)/$X14)*$D14,"") -> 0 | K14: =IFERROR(R14/$X14*$D14,"") -> 0 | L14: =IFERROR(S14/$X14*$D14,"") -> 0 | M14: =IFERROR(T14/$X14*$D14,"") -> 0 | N14: =IFERROR(U14/$X14*$D14,"") -> 0 | O14: =IFERROR(V14/$X14*$D14,"") -> 0 | P14: =IFERROR(W14/$X14*$D14,"") -> 0 | Q14: 90 | R14: 0 | S14: 0 | T14: 0 | U14: 0 | V14: 0 | W14: 0 | X14: =Y14*(Q14/100) -> 10886.4 | Y14: =24*5.25*48*D14 -> 12096 | Z14: 0 | AA14: 0 | AB14: 0 | AC14: 0 | AD14: 0 | AE14: 0 | AF14: =IFERROR(VLOOKUP(C14,'2_LN_DadosExportados'!V:V,1,FALSE),"") | AG14: {=IF(AND(ISERR(FIND("sim",INDEX('existencia de wc'!K$2:K$193,MATCH(IP_WC!C14,'existencia de wc'!B$2:B$192,0))))=FALSE,SUMPRODUCT(('2_LN_DadosExportados'!V$2:V$314=IP_WC!C14)*('2_LN_DadosExportados'!A$2:A$314="X"))>0), "MOSTRAR","")}
A15: =IF(OR(E15>=D15,F15>=D15,G15>=D15,H15>=D15,I15>=D15,J15>=D15),"INVEST","OK") -> OK | B15: HOR-0600 | C15: WC - Fer Ret Cil J&Ship 1300X | D15: 1 | E15: =IFERROR(((SUMIFS('2_LN_DadosExportados'!AM:AM,'2_LN_DadosExportados'!$V:$V,$C15,'2_LN_DadosExportados'!$A:$A,"X")+R15)/$X15)*$D15,"") -> 0 | F15: =IFERROR(((SUMIFS('2_LN_DadosExportados'!AN:AN,'2_LN_DadosExportados'!$V:$V,$C15,'2_LN_DadosExportados'!$A:$A,"X")+S15)/$X15)*$D15,"") -> 0 | G15: =IFERROR(((SUMIFS('2_LN_DadosExportados'!AO:AO,'2_LN_DadosExportados'!$V:$V,$C15,'2_LN_DadosExportados'!$A:$A,"X")+T15)/$X15)*$D15,"") -> 0 | H15: =IFERROR(((SUMIFS('2_LN_DadosExportados'!AP:AP,'2_LN_DadosExportados'!$V:$V,$C15,'2_LN_DadosExportados'!$A:$A,"X")+U15)/$X15)*$D15,"") -> 0 | I15: =IFERROR(((SUMIFS('2_LN_DadosExportados'!AQ:AQ,'2_LN_DadosExportados'!$V:$V,$C15,'2_LN_DadosExportados'!$A:$A,"X")+V15)/$X15)*$D15,"") -> 0 | J15: =IFERROR(((SUMIFS('2_LN_DadosExportados'!AR:AR,'2_LN_DadosExportados'!$V:$V,$C15,'2_LN_DadosExportados'!$A:$A,"X")+W15)/$X15)*$D15,"") -> 0 | K15: =IFERROR(R15/$X15*$D15,"") -> 0 | L15: =IFERROR(S15/$X15*$D15,"") -> 0 | M15: =IFERROR(T15/$X15*$D15,"") -> 0 | N15: =IFERROR(U15/$X15*$D15,"") -> 0 | O15: =IFERROR(V15/$X15*$D15,"") -> 0 | P15: =IFERROR(W15/$X15*$D15,"") -> 0 | Q15: 90 | R15: 0 | S15: 0 | T15: 0 | U15: 0 | V15: 0 | W15: 0 | X15: =Y15*(Q15/100) -> 5443.2 | Y15: =24*5.25*48*D15 -> 6048 | Z15: 0 | AA15: 0 | AB15: 0 | AC15: 0 | AD15: 0 | AE15: 0 | AF15: =IFERROR(VLOOKUP(C15,'2_LN_DadosExportados'!V:V,1,FALSE),"") | AG15: {=IF(AND(ISERR(FIND("sim",INDEX('existencia de wc'!K$2:K$193,MATCH(IP_WC!C15,'existencia de wc'!B$2:B$192,0))))=FALSE,SUMPRODUCT(('2_LN_DadosExportados'!V$2:V$314=IP_WC!C15)*('2_LN_DadosExportados'!A$2:A$314="X"))>0), "MOSTRAR","")}
... A78: =IF(OR(E78>=D78,F78>=D78,G78>=D78,H78>=D78,I78>=D78,J78>=D78),"INVEST","OK") -> INVEST | B78: UNDEFINED | C78: UNDEFINED | D78: 0 | E78: =IFERROR(((SUMIFS('2_LN_DadosExportados'!AM:AM,'2_LN_DadosExportados'!$V:$V,$C78,'2_LN_DadosExportados'!$A:$A,"X")+R78)/$X78)*$D78,"") | F78: =IFERROR(((SUMIFS('2_LN_DadosExportados'!AN:AN,'2_LN_DadosExportados'!$V:$V,$C78,'2_LN_DadosExportados'!$A:$A,"X")+S78)/$X78)*$D78,"") | G78: =IFERROR(((SUMIFS('2_LN_DadosExportados'!AO:AO,'2_LN_DadosExportados'!$V:$V,$C78,'2_LN_DadosExportados'!$A:$A,"X")+T78)/$X78)*$D78,"") | H78: =IFERROR(((SUMIFS('2_LN_DadosExportados'!AP:AP,'2_LN_DadosExportados'!$V:$V,$C78,'2_LN_DadosExportados'!$A:$A,"X")+U78)/$X78)*$D78,"") | I78: =IFERROR(((SUMIFS('2_LN_DadosExportados'!AQ:AQ,'2_LN_DadosExportados'!$V:$V,$C78,'2_LN_DadosExportados'!$A:$A,"X")+V78)/$X78)*$D78,"") | J78: =IFERROR(((SUMIFS('2_LN_DadosExportados'!AR:AR,'2_LN_DadosExportados'!$V:$V,$C78,'2_LN_DadosExportados'!$A:$A,"X")+W78)/$X78)*$D78,"") | K78: =IFERROR(R78/$X78*$D78,"") | L78: =IFERROR(S78/$X78*$D78,"") | M78: =IFERROR(T78/$X78*$D78,"") | N78: =IFERROR(U78/$X78*$D78,"") | O78: =IFERROR(V78/$X78*$D78,"") | P78: =IFERROR(W78/$X78*$D78,"") | Q78: 0 | R78: 0 | S78: 0 | T78: 0 | U78: 0 | V78: 0 | W78: 0 | X78: =Y78*(Q78/100) -> 0 | Y78: =24*5.25*48*D78 -> 0 | Z78: 5085629 | AA78: 1932059 | AB78: 1824639 | AC78: 1717220 | AD78: 1609800 | AE78: 1556090 | AF78: =IFERROR(VLOOKUP(C78,'2_LN_DadosExportados'!V:V,1,FALSE),"") | AG78: {=IF(AND(ISERR(FIND("sim",INDEX('existencia de wc'!K$2:K$193,MATCH(IP_WC!C78,'existencia de wc'!B$2:B$192,0))))=FALSE,SUMPRODUCT(('2_LN_DadosExportados'!V$2:V$314=IP_WC!C78)*('2_LN_DadosExportados'!A$2:A$314="X"))>0), "MOSTRAR","")}

Sheet 2_LN_DadosExportados
C1: Item fabricado | E1: Lead time ordem | G1: Roteiro | I1: Unidade de roteiro | M1: Operação | O1: Próxima operação | P1: Ponto de contagem | Q1: Backflushing | R1: Taxa de produção | S1: Tarefa | U1: Cent. Trab. | W1: Máquina | Y1: Tempo config médio [min] | Z1: Lote de transferênc. < lote de produção | AA1: Tempo de ciclo [min] | AB1: Transferência em lote | AC1: Data efetiva | AE1: Data vencimento | AG1: Fator da taxa de subcontratação | AH1: Ocupação de mão-de-obra | AI1: Ocupação de MO para produção | AJ1: Ocupação da máquina | AK1: Duração fixa | AM1: 2026 | AN1: 2027 | AO1: 2028 | AP1: 2029 | AQ1: 2030
A2: =VLOOKUP(C2,'1_RFQ_DadosVendas'!B:R,17,FALSE) -> 0 | C2: RFQ102030 | D2: ROTOR (3.06971.00.0) | E2: 13 | F2: Dias | G2: 1 | H2: Principal | I2: 1 | J2: pc | M2: 20 | N2: 1 | O2: 0 | P2: Não | Q2: Sim | R2: 1176 | S2: 3101 | T2: Sinterizar | U2: 3100 | V2: WC - Sin Abbott RapidCool 1/2 | W2: 1434 | X2: Sin Abbott 2 - Rapid Cooling | Y2: 90 | Z2: Não | AA2: 0.051 | AB2: 0 | AC2: 42094 | AD2: 0.44721065 | AE2: 50424 | AF2: 0.051469907 | AG2: 0 | AH2: 1 | AI2: 0.7 | AJ2: 1 | AK2: Não | AM2: =IFERROR(VLOOKUP(C2,'1_RFQ_DadosVendas'!B:Q,12,FALSE)/$R2,"") -> 170.06803 | AN2: =IFERROR(VLOOKUP($C2,'1_RFQ_DadosVendas'!$B:$Q,13,FALSE)/$R2,"") -> 170.06803 | AO2: =IFERROR(VLOOKUP($C2,'1_RFQ_DadosVendas'!$B:$Q,14,FALSE)/$R2,"") -> 170.06803 | AP2: =IFERROR(VLOOKUP($C2,'1_RFQ_DadosVendas'!$B:$Q,15,FALSE)/$R2,"") -> 170.06803 | AQ2: =IFERROR(VLOOKUP($C2,'1_RFQ_DadosVendas'!$B:$Q,16,FALSE)/$R2,"") -> 170.06803
A3: =VLOOKUP(C3,'1_RFQ_DadosVendas'!B:R,17,FALSE) -> 0 | C3: RFQ102030 | D3: ROTOR (3.06971.00.0) | E3: 13 | F3: Dias | G3: 1 | H3: Principal | I3: 1 | J3: pc | M3: 30 | N3: 1 | O3: 0 | P3: Não | Q3: Sim | R3: 1176 | S3: 7302 | T3: Olear | U3: 7300 | V3: WC - Oleamento | W3: 2201 | X3: Ole TANQUE OLEAM. SINTERIZAÇÃO | Y3: 0 | Z3: Não | AA3: 0.051 | AB3: 0 | AC3: 42094 | AD3: 0.4481713 | AE3: 50424 | AF3: 0.051469907 | AG3: 0 | AH3: 0 | AI3: 0.12 | AJ3: 1 | AK3: Não | AM3: =IFERROR(VLOOKUP(C3,'1_RFQ_DadosVendas'!B:Q,12,FALSE)/$R3,"") -> 170.06803 | AN3: =IFERROR(VLOOKUP($C3,'1_RFQ_DadosVendas'!$B:$Q,13,FALSE)/$R3,"") -> 170.06803 | AO3: =IFERROR(VLOOKUP($C3,'1_RFQ_DadosVendas'!$B:$Q,14,FALSE)/$R3,"") -> 170.06803 | AP3: =IFERROR(VLOOKUP($C3,'1_RFQ_DadosVendas'!$B:$Q,15,FALSE)/$R3,"") -> 170.06803 | AQ3: =IFERROR(VLOOKUP($C3,'1_RFQ_DadosVendas'!$B:$Q,16,FALSE)/$R3,"") -> 170.06803
A4: =VLOOKUP(C4,'1_RFQ_DadosVendas'!B:R,17,FALSE) -> 0 | C4: RFQ102030 | D4: ROTOR (3.06971.00.0) | E4: 13 | F4: Dias | G4: 1 | H4: Principal | I4: 1 | J4: pc | M4: 40 | N4: 2 | O4: 0 | P4: Sim | Q4: Sim | R4: 2000 | S4: 8206 | T4: Embalar para subcontratado | U4: 8101 | V4: WC - Embalagem manual | W4: 908101 | X4: # POSTO INSP/EMBALAGEM 90 | Y4: 0 | Z4: Não | AA4: 0.03 | AB4: 0 | AC4: 45168 | AD4: 0.64762731 | AE4: 50424 | AF4: 0.051469907 | AG4: 0 | AH4: 0 | AI4: 1 | AJ4: 1 | AK4: Não | AM4: =IFERROR(VLOOKUP(C4,'1_RFQ_DadosVendas'!B:Q,12,FALSE)/$R4,"") -> 100 | AN4: =IFERROR(VLOOKUP($C4,'1_RFQ_DadosVendas'!$B:$Q,13,FALSE)/$R4,"") -> 100 | AO4: =IFERROR(VLOOKUP($C4,'1_RFQ_DadosVendas'!$B:$Q,14,FALSE)/$R4,"") -> 100 | AP4: =IFERROR(VLOOKUP($C4,'1_RFQ_DadosVendas'!$B:$Q,15,FALSE)/$R4,"") -> 100 | AQ4: =IFERROR(VLOOKUP($C4,'1_RFQ_DadosVendas'!$B:$Q,16,FALSE)/$R4,"") -> 100
A5: =VLOOKUP(C5,'1_RFQ_DadosVendas'!B:R,17,FALSE) -> 0 | C5: RFQ102030 | D5: ROTOR (3.06971.00.0) | E5: 13 | F5: Dias | G5: 1 | H5: Principal | I5: 1 | J5: pc | M5: 50 | N5: 1 | O5: 0 | P5: Não | Q5: Sim | S5: 8205 | T5: Expedir Subcontratado | U5: 8205 | V5: WC - Expedir Subcontratado | W5: 8205 | X5: # POSTO EXPEDIR SUBCONTRATADO | Y5: 0 | Z5: Não | AA5: 0 | AB5: 0 | AC5: 45273 | AD5: 0.42454861 | AE5: 50424 | AF5: 0.051469907 | AG5: 0 | AH5: 0 | AI5: 1 | AJ5: 1 | AK5: Sim | AM5: =IFERROR(VLOOKUP(C5,'1_RFQ_DadosVendas'!B:Q,12,FALSE)/$R5,"") | AN5: =IFERROR(VLOOKUP($C5,'1_RFQ_DadosVendas'!$B:$Q,13,FALSE)/$R5,"") | AO5: =IFERROR(VLOOKUP($C5,'1_RFQ_DadosVendas'!$B:$Q,14,FALSE)/$R5,"") | AP5: =IFERROR(VLOOKUP($C5,'1_RFQ_DadosVendas'!$B:$Q,15,FALSE)/$R5,"") | AQ5: =IFERROR(VLOOKUP($C5,'1_RFQ_DadosVendas'!$B:$Q,16,FALSE)/$R5,"")
A6: =VLOOKUP(C6,'1_RFQ_DadosVendas'!B:R,17,FALSE) -> 0 | C6: RFQ102030 | D6: ROTOR (3.06971.00.0) | E6: 13 | F6: Dias | G6: 1 | H6: Principal | I6: 1 | J6: pc | M6: 60 | N6: 2 | O6: 0 | P6: Sim | Q6: Não | S6: 4201 | T6: Subcontratado - Trat. Térmico | U6: 4007 | V6: WC - Sub_Sotherm | W6: 4007 | X6: Subcon Sotherm | Y6: 0 | Z6: Não | AA6: 0 | AB6: 0 | AC6: 45170 | AD6: 0.64179398 | AE6: 50424 | AF6: 0.051469907 | AG6: 1.4 | AH6: 0 | AI6: 1 | AJ6: 1 | AK6: Sim | AM6: =IFERROR(VLOOKUP(C6,'1_RFQ_DadosVendas'!B:Q,12,FALSE)/$R6,"") | AN6: =IFERROR(VLOOKUP($C6,'1_RFQ_DadosVendas'!$B:$Q,13,FALSE)/$R6,"") | AO6: =IFERROR(VLOOKUP($C6,'1_RFQ_DadosVendas'!$B:$Q,14,FALSE)/$R6,"") | AP6: =IFERROR(VLOOKUP($C6,'1_RFQ_DadosVendas'!$B:$Q,15,FALSE)/$R6,"") | AQ6: =IFERROR(VLOOKUP($C6,'1_RFQ_DadosVendas'!$B:$Q,16,FALSE)/$R6,"")
A7: =VLOOKUP(C7,'1_RFQ_DadosVendas'!B:R,17,FALSE) -> 0 | C7: RFQ102030 | D7: ROTOR (3.06971.00.0) | E7: 13 | F7: Dias | G7: 1 | H7: Principal | I7: 1 | J7: pc | M7: 70 | N7: 2 | O7: 0 | P7: Não | Q7: Sim | R7: 5000 | S7: 8406 | T7: Inspeção de Entrada | U7: 8401 | V7: WC - Inspecionar | W7: 908301 | X7: # POSTO DE INSPEÇÃO - 90 | Y7: 0 | Z7: Não | AA7: 0.012 | AB7: 0 | AC7: 45170 | AD7: 0.6415625 | AE7: 50424 | AF7: 0.051469907 | AG7: 0 | AH7: 0 | AI7: 1 | AJ7: 1 | AK7: Não | AM7: =IFERROR(VLOOKUP(C7,'1_RFQ_DadosVendas'!B:Q,12,FALSE)/$R7,"") -> 40 | AN7: =IFERROR(VLOOKUP($C7,'1_RFQ_DadosVendas'!$B:$Q,13,FALSE)/$R7,"") -> 40 | AO7: =IFERROR(VLOOKUP($C7,'1_RFQ_DadosVendas'!$B:$Q,14,FALSE)/$R7,"") -> 40 | AP7: =IFERROR(VLOOKUP($C7,'1_RFQ_DadosVendas'!$B:$Q,15,FALSE)/$R7,"") -> 40 | AQ7: =IFERROR(VLOOKUP($C7,'1_RFQ_DadosVendas'!$B:$Q,16,FALSE)/$R7,"") -> 40
A8: =VLOOKUP(C8,'1_RFQ_DadosVendas'!B:R,17,FALSE) -> 0 | C8: RFQ102030 | D8: ROTOR (3.06971.00.0) | E8: 13 | F8: Dias | G8: 1 | H8: Principal | I8: 1 | J8: pc | M8: 80 | N8: 1 | O8: 0 | P8: Não | Q8: Não | R8: 50 | S8: 6201 | T8: Tornear | U8: 6203 | V8: WC - Tor FAMAR Bi-SUB | W8: 2783 | X8: Tor FAMAR Bi-SUB | Y8: 210 | Z8: Sim | AA8: 1.2 | AB8: 99 | AC8: 45170 | AD8: 0.64128472 | AE8: 50424 | AF8: 0.051469907 | AG8: 0 | AH8: 1 | AI8: 1 | AJ8: 1 | AK8: Não | AM8: =IFERROR(VLOOKUP(C8,'1_RFQ_DadosVendas'!B:Q,12,FALSE)/$R8,"") -> 4000 | AN8: =IFERROR(VLOOKUP($C8,'1_RFQ_DadosVendas'!$B:$Q,13,FALSE)/$R8,"") -> 4000 | AO8: =IFERROR(VLOOKUP($C8,'1_RFQ_DadosVendas'!$B:$Q,14,FALSE)/$R8,"") -> 4000 | AP8: =IFERROR(VLOOKUP($C8,'1_RFQ_DadosVendas'!$B:$Q,15,FALSE)/$R8,"") -> 4000 | AQ8: =IFERROR(VLOOKUP($C8,'1_RFQ_DadosVendas'!$B:$Q,16,FALSE)/$R8,"") -> 4000
A9: =VLOOKUP(C9,'1_RFQ_DadosVendas'!B:R,17,FALSE) -> 0 | C9: RFQ102030 | D9: ROTOR (3.06971.00.0) | E9: 13 | F9: Dias | G9: 1 | H9: Principal | I9: 1 | J9: pc | M9: 90 | N9: 1 | O9: 0 | P9: Não | Q9: Sim | R9: 400 | S9: 8301 | T9: Selecionar Visual 100% | U9: 8302 | V9: WC - Selecionar 100% | W9: 908401 | X9: # POSTO DE SELEÇÃO 100% - 90 | Y9: 0 | Z9: Não | AA9: 0.15 | AB9: 0 | AC9: 45168 | AD9: 0.65070602 | AE9: 50424 | AF9: 0.051469907 | AG9: 0 | AH9: 0 | AI9: 1 | AJ9: 1 | AK9: Não | AM9: =IFERROR(VLOOKUP(C9,'1_RFQ_DadosVendas'!B:Q,12,FALSE)/$R9,"") -> 500 | AN9: =IFERROR(VLOOKUP($C9,'1_RFQ_DadosVendas'!$B:$Q,13,FALSE)/$R9,"") -> 500 | AO9: =IFERROR(VLOOKUP($C9,'1_RFQ_DadosVendas'!$B:$Q,14,FALSE)/$R9,"") -> 500 | AP9: =IFERROR(VLOOKUP($C9,'1_RFQ_DadosVendas'!$B:$Q,15,FALSE)/$R9,"") -> 500 | AQ9: =IFERROR(VLOOKUP($C9,'1_RFQ_DadosVendas'!$B:$Q,16,FALSE)/$R9,"") -> 500
A10: =VLOOKUP(C10,'1_RFQ_DadosVendas'!B:R,17,FALSE) -> 0 | C10: RFQ102030 | D10: ROTOR (3.06971.00.0) | E10: 13 | F10: Dias | G10: 1 | H10: Principal | I10: 1 | J10: pc | M10: 100 | N10: 1 | O10: 0 | P10: Não | Q10: Não | R10: 300 | S10: 8410 | T10: TESTE DE TORQUE | U10: 8401 | V10: WC - Inspecionar | W10: 908301 | X10: # POSTO DE INSPEÇÃO - 90 | Y10: 60 | Z10: Não | AA10: 0.2 | AB10: 0 | AC10: 45273 | AD10: 0.42982639 | AE10: 50424 | AF10: 0.051469907 | AG10: 0 | AH10: 1 | AI10: 1 | AJ10: 1 | AK10: Não | AM10: =IFERROR(VLOOKUP(C10,'1_RFQ_DadosVendas'!B:Q,12,FALSE)/$R10,"") -> 666.66667 | AN10: =IFERROR(VLOOKUP($C10,'1_RFQ_DadosVendas'!$B:$Q,13,FALSE)/$R10,"") -> 666.66667 | AO10: =IFERROR(VLOOKUP($C10,'1_RFQ_DadosVendas'!$B:$Q,14,FALSE)/$R10,"") -> 666.66667 | AP10: =IFERROR(VLOOKUP($C10,'1_RFQ_DadosVendas'!$B:$Q,15,FALSE)/$R10,"") -> 666.66667 | AQ10: =IFERROR(VLOOKUP($C10,'1_RFQ_DadosVendas'!$B:$Q,16,FALSE)/$R10,"") -> 666.66667
A11: =VLOOKUP(C11,'1_RFQ_DadosVendas'!B:R,17,FALSE) -> 0 | C11: RFQ102030 | D11: ROTOR (3.06971.00.0) | E11: 13 | F11: Dias | G11: 1 | H11: Principal | I11: 1 | J11: pc | M11: 110 | N11: 1 | O11: 0 | P11: Sim | Q11: Sim | R11: 2000 | S11: 8101 | T11: Embalar | U11: 8101 | V11: WC - Embalagem manual | W11: 908101 | X11: # POSTO INSP/EMBALAGEM 90 | Y11: 0 | Z11: Não | AA11: 0.03 | AB11: 0 | AC11: 45273 | AD11: 0.43122685 | AE11: 50424 | AF11: 0.051469907 | AG11: 0 | AH11: 0 | AI11: 0 | AJ11: 1 | AK11: Não | AM11: =IFERROR(VLOOKUP(C11,'1_RFQ_DadosVendas'!B:Q,12,FALSE)/$R11,"") -> 100 | AN11: =IFERROR(VLOOKUP($C11,'1_RFQ_DadosVendas'!$B:$Q,13,FALSE)/$R11,"") -> 100 | AO11: =IFERROR(VLOOKUP($C11,'1_RFQ_DadosVendas'!$B:$Q,14,FALSE)/$R11,"") -> 100 | AP11: =IFERROR(VLOOKUP($C11,'1_RFQ_DadosVendas'!$B:$Q,15,FALSE)/$R11,"") -> 100 | AQ11: =IFERROR(VLOOKUP($C11,'1_RFQ_DadosVendas'!$B:$Q,16,FALSE)/$R11,"") -> 100
A12: =VLOOKUP(C12,'1_RFQ_DadosVendas'!B:R,17,FALSE) -> 0 | C12: RFQ102030 | D12: ROTOR (3.06971.00.0) | E12: 13 | F12: Dias | G12: 1 | H12: Principal | I12: 1 | J12: pc | M12: 120 | N12: 1 | O12: 0 | P12: Não | Q12: Não | R12: 2000 | S12: 8412 | T12: INSP. SAFE LAUNCH | U12: 8401 | V12: WC - Inspecionar | W12: 908301 | X12: # POSTO DE INSPEÇÃO - 90 | Y12: 0 | Z12: Não | AA12: 0.03 | AB12: 0 | AC12: 45273 | AD12: 0.4315162 | AE12: 50424 | AF12: 0.051469907 | AG12: 0 | AH12: 0 | AI12: 1 | AJ12: 1 | AK12: Não | AM12: =IFERROR(VLOOKUP(C12,'1_RFQ_DadosVendas'!B:Q,12,FALSE)/$R12,"") -> 100 | AN12: =IFERROR(VLOOKUP($C12,'1_RFQ_DadosVendas'!$B:$Q,13,FALSE)/$R12,"") -> 100 | AO12: =IFERROR(VLOOKUP($C12,'1_RFQ_DadosVendas'!$B:$Q,14,FALSE)/$R12,"") -> 100 | AP12: =IFERROR(VLOOKUP($C12,'1_RFQ_DadosVendas'!$B:$Q,15,FALSE)/$R12,"") -> 100 | AQ12: =IFERROR(VLOOKUP($C12,'1_RFQ_DadosVendas'!$B:$Q,16,FALSE)/$R12,"") -> 100
A13: =VLOOKUP(C13,'1_RFQ_DadosVendas'!B:R,17,FALSE) -> 0 | C13: RFQ102030 | D13: ROTOR (3.06971.00.0) | E13: 13 | F13: Dias | G13: 1 | H13: Principal | I13: 1 | J13: pc | L13: F | M13: 130 | N13: 1 | O13: 0 | P13: Não | Q13: Sim | S13: 8414 | T13: Auditoria Final | U13: 8414 | V13: WC - Auditoria Final | W13: 908414 | X13: # POSTO DE AUDITORIA FINAL | Y13: 0 | Z13: Não | AA13: 0 | AB13: 0 | AC13: 45273 | AD13: 0.4319213 | AE13: 50424 | AF13: 0.051469907 | AG13: 0 | AH13: 0 | AI13: 1 | AJ13: 1 | AK13: Sim | AM13: =IFERROR(VLOOKUP(C13,'1_RFQ_DadosVendas'!B:Q,12,FALSE)/$R13,"") | AN13: =IFERROR(VLOOKUP($C13,'1_RFQ_DadosVendas'!$B:$Q,13,FALSE)/$R13,"") | AO13: =IFERROR(VLOOKUP($C13,'1_RFQ_DadosVendas'!$B:$Q,14,FALSE)/$R13,"") | AP13: =IFERROR(VLOOKUP($C13,'1_RFQ_DadosVendas'!$B:$Q,15,FALSE)/$R13,"") | AQ13: =IFERROR(VLOOKUP($C13,'1_RFQ_DadosVendas'!$B:$Q,16,FALSE)/$R13,"")
A14: =VLOOKUP(C14,'1_RFQ_DadosVendas'!B:R,17,FALSE) -> 0 | C14: RFQ405060 | D14: REACTION PLATE | E14: 2 | F14: Dias | G14: 1 | H14: PRINCIPAL | I14: 1000 | J14: pc | K14: I | M14: 5 | N14: 1 | O14: 0 | P14: Não | Q14: Sim | S14: 1601 | T14: Preparar Ferramenta Compactaçã | U14: 8013 | V14: WC - Preparação Ferrament - GF | W14: 801301 | X14: # POSTO PREPARAÇÃO FERRAMENTAL | Y14: 120 | Z14: Não | AA14: 0 | AB14: 0 | AC14: 45216 | AD14: 0.46988426 | AE14: 50424 | AF14: 0.051469907 | AG14: 0 | AH14: 1 | AI14: 1 | AJ14: 1 | AK14: Sim | AM14: =IFERROR(VLOOKUP(C14,'1_RFQ_DadosVendas'!B:Q,12,FALSE)/$R14,"") | AN14: =IFERROR(VLOOKUP($C14,'1_RFQ_DadosVendas'!$B:$Q,13,FALSE)/$R14,"") | AO14: =IFERROR(VLOOKUP($C14,'1_RFQ_DadosVendas'!$B:$Q,14,FALSE)/$R14,"") | AP14: =IFERROR(VLOOKUP($C14,'1_RFQ_DadosVendas'!$B:$Q,15,FALSE)/$R14,"") | AQ14: =IFERROR(VLOOKUP($C14,'1_RFQ_DadosVendas'!$B:$Q,16,FALSE)/$R14,"")
A15: =VLOOKUP(C15,'1_RFQ_DadosVendas'!B:R,17,FALSE) -> 0 | C15: RFQ405060 | D15: REACTION PLATE | E15: 2 | F15: Dias | G15: 1 | H15: PRINCIPAL | I15: 1000 | J15: pc | M15: 10 | N15: 1 | O15: 0 | P15: Sim | Q15: Sim | R15: 120 | S15: 2101 | T15: Compactar | U15: 2180 | V15: WC - Com KPP 450 t Osterw 1/2 | W15: 1993 | X15: Com 450 ton Osterwalder 2 | Y15: 330 | Z15: Não | AA15: 500 | AB15: 0 | AC15: 43605 | AD15: 0.42607639 | AE15: 50424 | AF15: 0.051469907 | AG15: 0 | AH15: 1 | AI15: 1 | AJ15: 1 | AK15: Não | AM15: =IFERROR(VLOOKUP(C15,'1_RFQ_DadosVendas'!B:Q,12,FALSE)/$R15,"") -> 0 | AN15: =IFERROR(VLOOKUP($C15,'1_RFQ_DadosVendas'!$B:$Q,13,FALSE)/$R15,"") -> 0 | AO15: =IFERROR(VLOOKUP($C15,'1_RFQ_DadosVendas'!$B:$Q,14,FALSE)/$R15,"") -> 1250 | AP15: =IFERROR(VLOOKUP($C15,'1_RFQ_DadosVendas'!$B:$Q,15,FALSE)/$R15,"") -> 1250 | AQ15: =IFERROR(VLOOKUP($C15,'1_RFQ_DadosVendas'!$B:$Q,16,FALSE)/$R15,"") -> 1250
A16: =VLOOKUP(C16,'1_RFQ_DadosVendas'!B:R,17,FALSE) -> 0 | C16: RFQ405060 | D16: REACTION PLATE | E16: 2 | F16: Dias | G16: 1 | H16: PRINCIPAL | I16: 1000 | J16: pc | M16: 20 | N16: 2 | O16: 0 | P16: Não | Q16: Sim | R16: 168 | S16: 3101 | T16: Sinterizar | U16: 3102 | V16: WC - Sin Abbott Convencional 3 | W16: 2264 | X16: OFF - Sin Abbott 3 | Y16: 90 | Z16: Sim | AA16: 357.143 | AB16: 33 | AC16: 40792 | AD16: 0.29166667 | AE16: 50423 | AF16: 0.875 | AG16: 0 | AH16: 0 | AI16: 0.7 | AJ16: 1 | AK16: Não | AM16: =IFERROR(VLOOKUP(C16,'1_RFQ_DadosVendas'!B:Q,12,FALSE)/$R16,"") -> 0 | AN16: =IFERROR(VLOOKUP($C16,'1_RFQ_DadosVendas'!$B:$Q,13,FALSE)/$R16,"") -> 0 | AO16: =IFERROR(VLOOKUP($C16,'1_RFQ_DadosVendas'!$B:$Q,14,FALSE)/$R16,"") -> 892.85714 | AP16: =IFERROR(VLOOKUP($C16,'1_RFQ_DadosVendas'!$B:$Q,15,FALSE)/$R16,"") -> 892.85714 | AQ16: =IFERROR(VLOOKUP($C16,'1_RFQ_DadosVendas'!$B:$Q,16,FALSE)/$R16,"") -> 892.85714
A17: =VLOOKUP(C17,'1_RFQ_DadosVendas'!B:R,17,FALSE) -> 0 | C17: RFQ405060 | D17: REACTION PLATE | E17: 2 | F17: Dias | G17: 1 | H17: PRINCIPAL | I17: 1000 | J17: pc | M17: 30 | N17: 1 | O17: 0 | P17: Não | Q17: Sim | R17: 120 | S17: 7501 | T17: Tamborear | U17: 7501 | V17: WC - Vib Rosler e Otocarva | W17: 11 | X17: Vib Rosler 1 | Y17: 60 | Z17: Não | AA17: 500 | AB17: 0 | AC17: 40781 | AD17: 0.29166667 | AE17: 50423 | AF17: 0.875 | AG17: 0 | AH17: 1 | AI17: 0.12 | AJ17: 1 | AK17: Não | AM17: =IFERROR(VLOOKUP(C17,'1_RFQ_DadosVendas'!B:Q,12,FALSE)/$R17,"") -> 0 | AN17: =IFERROR(VLOOKUP($C17,'1_RFQ_DadosVendas'!$B:$Q,13,FALSE)/$R17,"") -> 0 | AO17: =IFERROR(VLOOKUP($C17,'1_RFQ_DadosVendas'!$B:$Q,14,FALSE)/$R17,"") -> 1250 | AP17: =IFERROR(VLOOKUP($C17,'1_RFQ_DadosVendas'!$B:$Q,15,FALSE)/$R17,"") -> 1250 | AQ17: =IFERROR(VLOOKUP($C17,'1_RFQ_DadosVendas'!$B:$Q,16,FALSE)/$R17,"") -> 1250
A18: =VLOOKUP(C18,'1_RFQ_DadosVendas'!B:R,17,FALSE) -> 0 | C18: RFQ405060 | D18: REACTION PLATE | E18: 2 | F18: Dias | G18: 1 | H18: PRINCIPAL | I18: 1000 | J18: pc | M18: 35 | N18: 1 | O18: 0 | P18: Não | Q18: Sim | R18: 120 | S18: 7302 | T18: Olear | U18: 7300 | V18: WC - Oleamento | W18: 2029 | X18: Ole TANQUE OLEAM TAMBOREAMENTO | Y18: 0 | Z18: Sim | AA18: 500 | AB18: 33 | AC18: 43381 | AD18: 0.71052083 | AE18: 50424 | AF18: 0.051469907 | AG18: 0 | AH18: 0 | AI18: 0.12 | AJ18: 1 | AK18: Não | AM18: =IFERROR(VLOOKUP(C18,'1_RFQ_DadosVendas'!B:Q,12,FALSE)/$R18,"") -> 0 | AN18: =IFERROR(VLOOKUP($C18,'1_RFQ_DadosVendas'!$B:$Q,13,FALSE)/$R18,"") -> 0 | AO18: =IFERROR(VLOOKUP($C18,'1_RFQ_DadosVendas'!$B:$Q,14,FALSE)/$R18,"") -> 1250 | AP18: =IFERROR(VLOOKUP($C18,'1_RFQ_DadosVendas'!$B:$Q,15,FALSE)/$R18,"") -> 1250 | AQ18: =IFERROR(VLOOKUP($C18,'1_RFQ_DadosVendas'!$B:$Q,16,FALSE)/$R18,"") -> 1250
A19: =VLOOKUP(C19,'1_RFQ_DadosVendas'!B:R,17,FALSE) -> 0 | C19: RFQ405060 | D19: REACTION PLATE | E19: 2 | F19: Dias | G19: 1 | H19: PRINCIPAL | I19: 1000 | J19: pc | M19: 38 | N19: 1 | O19: 0 | P19: Não | Q19: Sim | S19: 6201 | T19: Tornear | U19: 6200 | V19: WC - Torno CNC Okuma 1/2/3/4 | W19: 33 | X19: Tor Okuma 1 | Y19: 60 | Z19: Não | AA19: 0 | AB19: 0 | AC19: 45834 | AD19: 0.64166667 | AE19: 50424 | AF19: 0.051469907 | AG19: 0 | AH19: 1 | AI19: 1 | AJ19: 1 | AK19: Não | AM19: =IFERROR(VLOOKUP(C19,'1_RFQ_DadosVendas'!B:Q,12,FALSE)/$R19,"") | AN19: =IFERROR(VLOOKUP($C19,'1_RFQ_DadosVendas'!$B:$Q,13,FALSE)/$R19,"") | AO19: =IFERROR(VLOOKUP($C19,'1_RFQ_DadosVendas'!$B:$Q,14,FALSE)/$R19,"") | AP19: =IFERROR(VLOOKUP($C19,'1_RFQ_DadosVendas'!$B:$Q,15,FALSE)/$R19,"") | AQ19: =IFERROR(VLOOKUP($C19,'1_RFQ_DadosVendas'!$B:$Q,16,FALSE)/$R19,"")
A20: =VLOOKUP(C20,'1_RFQ_DadosVendas'!B:R,17,FALSE) -> 0 | C20: RFQ405060 | D20: REACTION PLATE | E20: 2 | F20: Dias | G20: 1 | H20: PRINCIPAL | I20: 1000 | J20: pc | M20: 40 | N20: 2 | O20: 0 | P20: Sim | Q20: Sim | R20: 30000 | S20: 8101 | T20: Embalar | U20: 8101 | V20: WC - Embalagem manual | W20: 908101 | X20: # POSTO INSP/EMBALAGEM 90 | Y20: 0 | Z20: Sim | AA20: 2 | AB20: 33 | AC20: 43381 | AD20: 0.71072917 | AE20: 50424 | AF20: 0.051469907 | AG20: 0 | AH20: 0 | AI20: 1 | AJ20: 1 | AK20: Não | AM20: =IFERROR(VLOOKUP(C20,'1_RFQ_DadosVendas'!B:Q,12,FALSE)/$R20,"") -> 0 | AN20: =IFERROR(VLOOKUP($C20,'1_RFQ_DadosVendas'!$B:$Q,13,FALSE)/$R20,"") -> 0 | AO20: =IFERROR(VLOOKUP($C20,'1_RFQ_DadosVendas'!$B:$Q,14,FALSE)/$R20,"") -> 5 | AP20: =IFERROR(VLOOKUP($C20,'1_RFQ_DadosVendas'!$B:$Q,15,FALSE)/$R20,"") -> 5 | AQ20: =IFERROR(VLOOKUP($C20,'1_RFQ_DadosVendas'!$B:$Q,16,FALSE)/$R20,"") -> 5
A21: =VLOOKUP(C21,'1_RFQ_DadosVendas'!B:R,17,FALSE) -> 0 | C21: RFQ405060 | D21: REACTION PLATE | E21: 2 | F21: Dias | G21: 1 | H21: PRINCIPAL | I21: 1000 | J21: pc | L21: F | M21: 50 | N21: 1 | O21: 0 | P21: Não | Q21: Sim | S21: 8414 | T21: Auditoria Final | U21: 8414 | V21: WC - Auditoria Final | W21: 908414 | X21: # POSTO DE AUDITORIA FINAL | Y21: 0 | Z21: Não | AA21: 0 | AB21: 0 | AC21: 43381 | AD21: 0.71099537 | AE21: 50424 | AF21: 0.051469907 | AG21: 0 | AH21: 0 | AI21: 1 | AJ21: 1 | AK21: Sim | AM21: =IFERROR(VLOOKUP(C21,'1_RFQ_DadosVendas'!B:Q,12,FALSE)/$R21,"") | AN21: =IFERROR(VLOOKUP($C21,'1_RFQ_DadosVendas'!$B:$Q,13,FALSE)/$R21,"") | AO21: =IFERROR(VLOOKUP($C21,'1_RFQ_DadosVendas'!$B:$Q,14,FALSE)/$R21,"") | AP21: =IFERROR(VLOOKUP($C21,'1_RFQ_DadosVendas'!$B:$Q,15,FALSE)/$R21,"") | AQ21: =IFERROR(VLOOKUP($C21,'1_RFQ_DadosVendas'!$B:$Q,16,FALSE)/$R21,"")

Sheet 3_Industrial_Plan_Idash
D1: Req, machines | F1: Req. machines Strategy + RFQ | K1: Req, machines Strategy | Q1: Actual Oee (%) | R1: Req, capacity (h) Strategy | X1: Planned capacity (h) Strategy | AD1: Total capacity (h) Strategy | AJ1: Quantity Strategy
A2: NECESSÁRIO INVESTIR? | B2: Name | C2: Description | D2: Actual machine | E2: 2025 | F2: 2026 | G2: 2027 | H2: 2028 | I2: 2029 | J2: 2030 | K2: 2025 | L2: 2026 | M2: 2027 | N2: 2028 | O2: 2029 | P2: 2030 | Q2: Standard Oee | R2: 2025 | S2: 2026 | T2: 2027 | U2: 2028 | V2: 2029 | W2: 2030 | X2: 2025 | Y2: 2026 | Z2: 2027 | AA2: 2028 | AB2: 2029 | AC2: 2030 | AD2: 2025 | AE2: 2026 | AF2: 2027 | AG2: 2028 | AH2: 2029 | AI2: 2030 | AJ2: 2025 | AK2: 2026 | AL2: 2027 | AM2: 2028 | AN2: 2029 | AO2: 2030 | AP2: WC no RFQ | AQ2: TESTE 2
B3: Total | D3: =SUM(D4:D77) -> 91 | E3: =SUM(E4:E77) -> 40.301293 | F3: =SUM(F4:F77) -> 38.460879 | G3: =SUM(G4:G77) -> 38.662751 | H3: =SUM(H4:H77) -> 40.382061 | I3: =SUM(I4:I77) -> 42.734599 | J3: =SUM(J4:J77) -> 42.727974 | K3: =SUM(K4:K77) -> 40.301293 | ... AO3: =SUM(AO4:AO77) -> 308865224 | AP3: =IFERROR(VLOOKUP(D4,'2_LN_DadosExportados'!V:V,1,FALSE),"")
A4: =IF(OR(E4>=D4,F4>=D4,G4>=D4,H4>=D4,I4>=D4,J4>=D4),"INVEST","OK") -> OK | B4: HOR-0150 | C4: WC - Fer Tor ROMI Multiplic30D | D4: 1 | E4: =IFERROR(((SUMIFS('2_LN_DadosExportados'!AL:AL,'2_LN_DadosExportados'!$V:$V,$C4,'2_LN_DadosExportados'!$A:$A,"X")+R4)/X4)*$D4,"") -> 0 | F4: =IFERROR(((SUMIFS('2_LN_DadosExportados'!AM:AM,'2_LN_DadosExportados'!$V:$V,$C4,'2_LN_DadosExportados'!$A:$A,"X")+S4)/Y4)*$D4,"") -> 0 | G4: =IFERROR(((SUMIFS('2_LN_DadosExportados'!AN:AN,'2_LN_DadosExportados'!$V:$V,$C4,'2_LN_DadosExportados'!$A:$A,"X")+T4)/Z4)*$D4,"") -> 0 | H4: =IFERROR(((SUMIFS('2_LN_DadosExportados'!AO:AO,'2_LN_DadosExportados'!$V:$V,$C4,'2_LN_DadosExportados'!$A:$A,"X")+U4)/AA4)*$D4,"") -> 0 | I4: =IFERROR(((SUMIFS('2_LN_DadosExportados'!AP:AP,'2_LN_DadosExportados'!$V:$V,$C4,'2_LN_DadosExportados'!$A:$A,"X")+V4)/AB4)*$D4,"") -> 0 | J4: =IFERROR(((SUMIFS('2_LN_DadosExportados'!AQ:AQ,'2_LN_DadosExportados'!$V:$V,$C4,'2_LN_DadosExportados'!$A:$A,"X")+W4)/AC4)*$D4,"") -> 0 | K4: =IFERROR(R4/X4*$D4,"") -> 0 | L4: =IFERROR(S4/Y4*$D4,"") -> 0 | M4: =IFERROR(T4/Z4*$D4,"") -> 0 | N4: =IFERROR(U4/AA4*$D4,"") -> 0 | O4: =IFERROR(V4/AB4*$D4,"") -> 0 | P4: =IFERROR(W4/AC4*$D4,"") -> 0 | Q4: 90 | R4: 0 | S4: 0 | T4: 0 | U4: 0 | V4: 0 | W4: 0 | X4: =AD4*($Q4/100) -> 4348.8 | Y4: =AE4*($Q4/100) -> 4095 | Z4: =AF4*($Q4/100) -> 4336.11 | AA4: =AG4*($Q4/100) -> 4329.27 | AB4: =AH4*($Q4/100) -> 4328.64 | AC4: =AI4*($Q4/100) -> 4367.25 | AD4: 4832 | AE4: 4550 | AF4: 4817.9 | AG4: 4810.3 | AH4: 4809.6 | AI4: 4852.5 | AJ4: 0 | AK4: 0 | AL4: 0 | AM4: 0 | AN4: 0 | AO4: 0 | AP4: =IFERROR(VLOOKUP(C4,'2_LN_DadosExportados'!V:V,1,FALSE),"") | AQ4: {=IF(AND(ISERR(FIND("sim",INDEX('existencia de wc'!K$2:K$193,MATCH('3_Industrial_Plan_Idash'!C4,'existencia de wc'!B$2:B$192,0))))=FALSE,SUMPRODUCT(('2_LN_DadosExportados'!V$2:V$314='3_Industrial_Plan_Idash'!C4)*('2_LN_DadosExportados'!A$2:A$314="X"))>0), "MOSTRAR","")}
A5: =IF(OR(E5>=D5,F5>=D5,G5>=D5,H5>=D5,I5>=D5,J5>=D5),"INVEST","OK") -> OK | B5: HOR-0160 | C5: WC - Fer Torno Mazak Integrex | D5: 1 | E5: =IFERROR(((SUMIFS('2_LN_DadosExportados'!AL:AL,'2_LN_DadosExportados'!$V:$V,$C5,'2_LN_DadosExportados'!$A:$A,"X")+R5)/X5)*$D5,"") -> 0 | F5: =IFERROR(((SUMIFS('2_LN_DadosExportados'!AM:AM,'2_LN_DadosExportados'!$V:$V,$C5,'2_LN_DadosExportados'!$A:$A,"X")+S5)/Y5)*$D5,"") -> 0 | G5: =IFERROR(((SUMIFS('2_LN_DadosExportados'!AN:AN,'2_LN_DadosExportados'!$V:$V,$C5,'2_LN_DadosExportados'!$A:$A,"X")+T5)/Z5)*$D5,"") -> 0 | H5: =IFERROR(((SUMIFS('2_LN_DadosExportados'!AO:AO,'2_LN_DadosExportados'!$V:$V,$C5,'2_LN_DadosExportados'!$A:$A,"X")+U5)/AA5)*$D5,"") -> 0 | I5: =IFERROR(((SUMIFS('2_LN_DadosExportados'!AP:AP,'2_LN_DadosExportados'!$V:$V,$C5,'2_LN_DadosExportados'!$A:$A,"X")+V5)/AB5)*$D5,"") -> 0 | J5: =IFERROR(((SUMIFS('2_LN_DadosExportados'!AQ:AQ,'2_LN_DadosExportados'!$V:$V,$C5,'2_LN_DadosExportados'!$A:$A,"X")+W5)/AC5)*$D5,"") -> 0 | K5: =IFERROR(R5/X5*$D5,"") -> 0 | L5: =IFERROR(S5/Y5*$D5,"") -> 0 | M5: =IFERROR(T5/Z5*$D5,"") -> 0 | N5: =IFERROR(U5/AA5*$D5,"") -> 0 | O5: =IFERROR(V5/AB5*$D5,"") -> 0 | P5: =IFERROR(W5/AC5*$D5,"") -> 0 | Q5: 90 | R5: 0 | S5: 0 | T5: 0 | U5: 0 | V5: 0 | W5: 0 | X5: =AD5*($Q5/100) -> 4348.8 | Y5: =AE5*($Q5/100) -> 4095 | Z5: =AF5*($Q5/100) -> 4336.11 | AA5: =AG5*($Q5/100) -> 4329.27 | AB5: =AH5*($Q5/100) -> 4328.64 | AC5: =AI5*($Q5/100) -> 4367.25 | AD5: 4832 | AE5: 4550 | AF5: 4817.9 | AG5: 4810.3 | AH5: 4809.6 | AI5: 4852.5 | AJ5: 0 | AK5: 0 | AL5: 0 | AM5: 0 | AN5: 0 | AO5: 0 | AP5: =IFERROR(VLOOKUP(C5,'2_LN_DadosExportados'!V:V,1,FALSE),"") | AQ5: {=IF(AND(ISERR(FIND("sim",INDEX('existencia de wc'!K$2:K$193,MATCH('3_Industrial_Plan_Idash'!C5,'existencia de wc'!B$2:B$192,0))))=FALSE,SUMPRODUCT(('2_LN_DadosExportados'!V$2:V$314='3_Industrial_Plan_Idash'!C5)*('2_LN_DadosExportados'!A$2:A$314="X"))>0), "MOSTRAR","")}
A6: =IF(OR(E6>=D6,F6>=D6,G6>=D6,H6>=D6,I6>=D6,J6>=D6),"INVEST","OK") -> OK | B6: HOR-0201 | C6: WC - Fer Fresadora | D6: 1 | E6: =IFERROR(((SUMIFS('2_LN_DadosExportados'!AL:AL,'2_LN_DadosExportados'!$V:$V,$C6,'2_LN_DadosExportados'!$A:$A,"X")+R6)/X6)*$D6,"") -> 0 | F6: =IFERROR(((SUMIFS('2_LN_DadosExportados'!AM:AM,'2_LN_DadosExportados'!$V:$V,$C6,'2_LN_DadosExportados'!$A:$A,"X")+S6)/Y6)*$D6,"") -> 0 | G6: =IFERROR(((SUMIFS('2_LN_DadosExportados'!AN:AN,'2_LN_DadosExportados'!$V:$V,$C6,'2_LN_DadosExportados'!$A:$A,"X")+T6)/Z6)*$D6,"") -> 0 | H6: =IFERROR(((SUMIFS('2_LN_DadosExportados'!AO:AO,'2_LN_DadosExportados'!$V:$V,$C6,'2_LN_DadosExportados'!$A:$A,"X")+U6)/AA6)*$D6,"") -> 0 | I6: =IFERROR(((SUMIFS('2_LN_DadosExportados'!AP:AP,'2_LN_DadosExportados'!$V:$V,$C6,'2_LN_DadosExportados'!$A:$A,"X")+V6)/AB6)*$D6,"") -> 0 | J6: =IFERROR(((SUMIFS('2_LN_DadosExportados'!AQ:AQ,'2_LN_DadosExportados'!$V:$V,$C6,'2_LN_DadosExportados'!$A:$A,"X")+W6)/AC6)*$D6,"") -> 0 | K6: =IFERROR(R6/X6*$D6,"") -> 0 | L6: =IFERROR(S6/Y6*$D6,"") -> 0 | M6: =IFERROR(T6/Z6*$D6,"") -> 0 | N6: =IFERROR(U6/AA6*$D6,"") -> 0 | O6: =IFERROR(V6/AB6*$D6,"") -> 0 | P6: =IFERROR(W6/AC6*$D6,"") -> 0 | Q6: 90 | R6: 0 | S6: 0 | T6: 0 | U6: 0 | V6: 0 | W6: 0 | X6: =AD6*($Q6/100) -> 4348.8 | Y6: =AE6*($Q6/100) -> 4095 | Z6: =AF6*($Q6/100) -> 4336.11 | AA6: =AG6*($Q6/100) -> 4329.27 | AB6: =AH6*($Q6/100) -> 4328.64 | AC6: =AI6*($Q6/100) -> 4367.25 | AD6: 4832 | AE6: 4550 | AF6: 4817.9 | AG6: 4810.3 | AH6: 4809.6 | AI6: 4852.5 | AJ6: 0 | AK6: 0 | AL6: 0 | AM6: 0 | AN6: 0 | AO6: 0 | AP6: =IFERROR(VLOOKUP(C6,'2_LN_DadosExportados'!V:V,1,FALSE),"") | AQ6: {=IF(AND(ISERR(FIND("sim",INDEX('existencia de wc'!K$2:K$193,MATCH('3_Industrial_Plan_Idash'!C6,'existencia de wc'!B$2:B$192,0))))=FALSE,SUMPRODUCT(('2_LN_DadosExportados'!V$2:V$314='3_Industrial_Plan_Idash'!C6)*('2_LN_DadosExportados'!A$2:A$314="X"))>0), "MOSTRAR","")}
A7: =IF(OR(E7>=D7,F7>=D7,G7>=D7,H7>=D7,I7>=D7,J7>=D7),"INVEST","OK") -> OK | B7: HOR-0300 | C7: WC - Fer Eletro Fio Challenge | D7: 1 | E7: =IFERROR(((SUMIFS('2_LN_DadosExportados'!AL:AL,'2_LN_DadosExportados'!$V:$V,$C7,'2_LN_DadosExportados'!$A:$A,"X")+R7)/X7)*$D7,"") -> 0 | F7: =IFERROR(((SUMIFS('2_LN_DadosExportados'!AM:AM,'2_LN_DadosExportados'!$V:$V,$C7,'2_LN_DadosExportados'!$A:$A,"X")+S7)/Y7)*$D7,"") -> 0 | G7: =IFERROR(((SUMIFS('2_LN_DadosExportados'!AN:AN,'2_LN_DadosExportados'!$V:$V,$C7,'2_LN_DadosExportados'!$A:$A,"X")+T7)/Z7)*$D7,"") -> 0 | H7: =IFERROR(((SUMIFS('2_LN_DadosExportados'!AO:AO,'2_LN_DadosExportados'!$V:$V,$C7,'2_LN_DadosExportados'!$A:$A,"X")+U7)/AA7)*$D7,"") -> 0 | I7: =IFERROR(((SUMIFS('2_LN_DadosExportados'!AP:AP,'2_LN_DadosExportados'!$V:$V,$C7,'2_LN_DadosExportados'!$A:$A,"X")+V7)/AB7)*$D7,"") -> 0 | J7: =IFERROR(((SUMIFS('2_LN_DadosExportados'!AQ:AQ,'2_LN_DadosExportados'!$V:$V,$C7,'2_LN_DadosExportados'!$A:$A,"X")+W7)/AC7)*$D7,"") -> 0 | K7: =IFERROR(R7/X7*$D7,"") -> 0 | L7: =IFERROR(S7/Y7*$D7,"") -> 0 | M7: =IFERROR(T7/Z7*$D7,"") -> 0 | N7: =IFERROR(U7/AA7*$D7,"") -> 0 | O7: =IFERROR(V7/AB7*$D7,"") -> 0 | P7: =IFERROR(W7/AC7*$D7,"") -> 0 | Q7: 90 | R7: 0 | S7: 0 | T7: 0 | U7: 0 | V7: 0 | W7: 0 | X7: =AD7*($Q7/100) -> 4348.8 | Y7: =AE7*($Q7/100) -> 4095 | Z7: =AF7*($Q7/100) -> 4336.11 | AA7: =AG7*($Q7/100) -> 4329.27 | AB7: =AH7*($Q7/100) -> 4328.64 | AC7: =AI7*($Q7/100) -> 4367.25 | AD7: 4832 | AE7: 4550 | AF7: 4817.9 | AG7: 4810.3 | AH7: 4809.6 | AI7: 4852.5 | AJ7: 0 | AK7: 0 | AL7: 0 | AM7: 0 | AN7: 0 | AO7: 0 | AP7: =IFERROR(VLOOKUP(C7,'2_LN_DadosExportados'!V:V,1,FALSE),"") | AQ7: {=IF(AND(ISERR(FIND("sim",INDEX('existencia de wc'!K$2:K$193,MATCH('3_Industrial_Plan_Idash'!C7,'existencia de wc'!B$2:B$192,0))))=FALSE,SUMPRODUCT(('2_LN_DadosExportados'!V$2:V$314='3_Industrial_Plan_Idash'!C7)*('2_LN_DadosExportados'!A$2:A$314="X"))>0), "MOSTRAR","")}
A8: =IF(OR(E8>=D8,F8>=D8,G8>=D8,H8>=D8,I8>=D8,J8>=D8),"INVEST","OK") -> OK | B8: HOR-0310 | C8: WC - Fer Eletro Furo Rápido | D8: 1 | E8: =IFERROR(((SUMIFS('2_LN_DadosExportados'!AL:AL,'2_LN_DadosExportados'!$V:$V,$C8,'2_LN_DadosExportados'!$A:$A,"X")+R8)/X8)*$D8,"") -> 0 | F8: =IFERROR(((SUMIFS('2_LN_DadosExportados'!AM:AM,'2_LN_DadosExportados'!$V:$V,$C8,'2_LN_DadosExportados'!$A:$A,"X")+S8)/Y8)*$D8,"") -> 0 | G8: =IFERROR(((SUMIFS('2_LN_DadosExportados'!AN:AN,'2_LN_DadosExportados'!$V:$V,$C8,'2_LN_DadosExportados'!$A:$A,"X")+T8)/Z8)*$D8,"") -> 0 | H8: =IFERROR(((SUMIFS('2_LN_DadosExportados'!AO:AO,'2_LN_DadosExportados'!$V:$V,$C8,'2_LN_DadosExportados'!$A:$A,"X")+U8)/AA8)*$D8,"") -> 0 | I8: =IFERROR(((SUMIFS('2_LN_DadosExportados'!AP:AP,'2_LN_DadosExportados'!$V:$V,$C8,'2_LN_DadosExportados'!$A:$A,"X")+V8)/AB8)*$D8,"") -> 0 | J8: =IFERROR(((SUMIFS('2_LN_DadosExportados'!AQ:AQ,'2_LN_DadosExportados'!$V:$V,$C8,'2_LN_DadosExportados'!$A:$A,"X")+W8)/AC8)*$D8,"") -> 0 | K8: =IFERROR(R8/X8*$D8,"") -> 0 | L8: =IFERROR(S8/Y8*$D8,"") -> 0 | M8: =IFERROR(T8/Z8*$D8,"") -> 0 | N8: =IFERROR(U8/AA8*$D8,"") -> 0 | O8: =IFERROR(V8/AB8*$D8,"") -> 0 | P8: =IFERROR(W8/AC8*$D8,"") -> 0 | Q8: 90 | R8: 0 | S8: 0 | T8: 0 | U8: 0 | V8: 0 | W8: 0 | X8: =AD8*($Q8/100) -> 4348.8 | Y8: =AE8*($Q8/100) -> 4095 | Z8: =AF8*($Q8/100) -> 4336.11 | AA8: =AG8*($Q8/100) -> 4329.27 | AB8: =AH8*($Q8/100) -> 4328.64 | AC8: =AI8*($Q8/100) -> 4367.25 | AD8: 4832 | AE8: 4550 | AF8: 4817.9 | AG8: 4810.3 | AH8: 4809.6 | AI8: 4852.5 | AJ8: 0 | AK8: 0 | AL8: 0 | AM8: 0 | AN8: 0 | AO8: 0 | AP8: =IFERROR(VLOOKUP(C8,'2_LN_DadosExportados'!V:V,1,FALSE),"") | AQ8: {=IF(AND(ISERR(FIND("sim",INDEX('existencia de wc'!K$2:K$193,MATCH('3_Industrial_Plan_Idash'!C8,'existencia de wc'!B$2:B$192,0))))=FALSE,SUMPRODUCT(('2_LN_DadosExportados'!V$2:V$314='3_Industrial_Plan_Idash'!C8)*('2_LN_DadosExportados'!A$2:A$314="X"))>0), "MOSTRAR","")}
A9: =IF(OR(E9>=D9,F9>=D9,G9>=D9,H9>=D9,I9>=D9,J9>=D9),"INVEST","OK") -> OK | B9: HOR-0311 | C9: WC - Fer Penet Form P600 | D9: 1 | E9: =IFERROR(((SUMIFS('2_LN_DadosExportados'!AL:AL,'2_LN_DadosExportados'!$V:$V,$C9,'2_LN_DadosExportados'!$A:$A,"X")+R9)/X9)*$D9,"") -> 0 | F9: =IFERROR(((SUMIFS('2_LN_DadosExportados'!AM:AM,'2_LN_DadosExportados'!$V:$V,$C9,'2_LN_DadosExportados'!$A:$A,"X")+S9)/Y9)*$D9,"") -> 0 | G9: =IFERROR(((SUMIFS('2_LN_DadosExportados'!AN:AN,'2_LN_DadosExportados'!$V:$V,$C9,'2_LN_DadosExportados'!$A:$A,"X")+T9)/Z9)*$D9,"") -> 0 | H9: =IFERROR(((SUMIFS('2_LN_DadosExportados'!AO:AO,'2_LN_DadosExportados'!$V:$V,$C9,'2_LN_DadosExportados'!$A:$A,"X")+U9)/AA9)*$D9,"") -> 0 | I9: =IFERROR(((SUMIFS('2_LN_DadosExportados'!AP:AP,'2_LN_DadosExportados'!$V:$V,$C9,'2_LN_DadosExportados'!$A:$A,"X")+V9)/AB9)*$D9,"") -> 0 | J9: =IFERROR(((SUMIFS('2_LN_DadosExportados'!AQ:AQ,'2_LN_DadosExportados'!$V:$V,$C9,'2_LN_DadosExportados'!$A:$A,"X")+W9)/AC9)*$D9,"") -> 0 | K9: =IFERROR(R9/X9*$D9,"") -> 0 | L9: =IFERROR(S9/Y9*$D9,"") -> 0 | M9: =IFERROR(T9/Z9*$D9,"") -> 0 | N9: =IFERROR(U9/AA9*$D9,"") -> 0 | O9: =IFERROR(V9/AB9*$D9,"") -> 0 | P9: =IFERROR(W9/AC9*$D9,"") -> 0 | Q9: 90 | R9: 0 | S9: 0 | T9: 0 | U9: 0 | V9: 0 | W9: 0 | X9: =AD9*($Q9/100) -> 4348.8 | Y9: =AE9*($Q9/100) -> 4095 | Z9: =AF9*($Q9/100) -> 4336.11 | AA9: =AG9*($Q9/100) -> 4329.27 | AB9: =AH9*($Q9/100) -> 4328.64 | AC9: =AI9*($Q9/100) -> 4367.25 | AD9: 4832 | AE9: 4550 | AF9: 4817.9 | AG9: 4810.3 | AH9: 4809.6 | AI9: 4852.5 | AJ9: 0 | AK9: 0 | AL9: 0 | AM9: 0 | AN9: 0 | AO9: 0 | AP9: =IFERROR(VLOOKUP(C9,'2_LN_DadosExportados'!V:V,1,FALSE),"") | AQ9: {=IF(AND(ISERR(FIND("sim",INDEX('existencia de wc'!K$2:K$193,MATCH('3_Industrial_Plan_Idash'!C9,'existencia de wc'!B$2:B$192,0))))=FALSE,SUMPRODUCT(('2_LN_DadosExportados'!V$2:V$314='3_Industrial_Plan_Idash'!C9)*('2_LN_DadosExportados'!A$2:A$314="X"))>0), "MOSTRAR","")}
A10: =IF(OR(E10>=D10,F10>=D10,G10>=D10,H10>=D10,I10>=D10,J10>=D10),"INVEST","OK") -> OK | B10: HOR-0313 | C10: WC - Fer Penetração Hiper Sp | D10: 1 | E10: =IFERROR(((SUMIFS('2_LN_DadosExportados'!AL:AL,'2_LN_DadosExportados'!$V:$V,$C10,'2_LN_DadosExportados'!$A:$A,"X")+R10)/X10)*$D10,"") -> 0 | F10: =IFERROR(((SUMIFS('2_LN_DadosExportados'!AM:AM,'2_LN_DadosExportados'!$V:$V,$C10,'2_LN_DadosExportados'!$A:$A,"X")+S10)/Y10)*$D10,"") -> 0 | G10: =IFERROR(((SUMIFS('2_LN_DadosExportados'!AN:AN,'2_LN_DadosExportados'!$V:$V,$C10,'2_LN_DadosExportados'!$A:$A,"X")+T10)/Z10)*$D10,"") -> 0 | H10: =IFERROR(((SUMIFS('2_LN_DadosExportados'!AO:AO,'2_LN_DadosExportados'!$V:$V,$C10,'2_LN_DadosExportados'!$A:$A,"X")+U10)/AA10)*$D10,"") -> 0 | I10: =IFERROR(((SUMIFS('2_LN_DadosExportados'!AP:AP,'2_LN_DadosExportados'!$V:$V,$C10,'2_LN_DadosExportados'!$A:$A,"X")+V10)/AB10)*$D10,"") -> 0 | J10: =IFERROR(((SUMIFS('2_LN_DadosExportados'!AQ:AQ,'2_LN_DadosExportados'!$V:$V,$C10,'2_LN_DadosExportados'!$A:$A,"X")+W10)/AC10)*$D10,"") -> 0 | K10: =IFERROR(R10/X10*$D10,"") -> 0 | L10: =IFERROR(S10/Y10*$D10,"") -> 0 | M10: =IFERROR(T10/Z10*$D10,"") -> 0 | N10: =IFERROR(U10/AA10*$D10,"") -> 0 | O10: =IFERROR(V10/AB10*$D10,"") -> 0 | P10: =IFERROR(W10/AC10*$D10,"") -> 0 | Q10: 90 | R10: 0 | S10: 0 | T10: 0 | U10: 0 | V10: 0 | W10: 0 | X10: =AD10*($Q10/100) -> 4348.8 | Y10: =AE10*($Q10/100) -> 4095 | Z10: =AF10*($Q10/100) -> 4336.11 | AA10: =AG10*($Q10/100) -> 4329.27 | AB10: =AH10*($Q10/100) -> 4328.64 | AC10: =AI10*($Q10/100) -> 4367.25 | AD10: 4832 | AE10: 4550 | AF10: 4817.9 | AG10: 4810.3 | AH10: 4809.6 | AI10: 4852.5 | AJ10: 0 | AK10: 0 | AL10: 0 | AM10: 0 | AN10: 0 | AO10: 0 | AP10: =IFERROR(VLOOKUP(C10,'2_LN_DadosExportados'!V:V,1,FALSE),"") | AQ10: {=IF(AND(ISERR(FIND("sim",INDEX('existencia de wc'!K$2:K$193,MATCH('3_Industrial_Plan_Idash'!C10,'existencia de wc'!B$2:B$192,0))))=FALSE,SUMPRODUCT(('2_LN_DadosExportados'!V$2:V$314='3_Industrial_Plan_Idash'!C10)*('2_LN_DadosExportados'!A$2:A$314="X"))>0), "MOSTRAR","")}
A11: =IF(OR(E11>=D11,F11>=D11,G11>=D11,H11>=D11,I11>=D11,J11>=D11),"INVEST","OK") -> OK | B11: HOR-0314 | C11: WC - Fer Penetração Form 20 | D11: 1 | E11: =IFERROR(((SUMIFS('2_LN_DadosExportados'!AL:AL,'2_LN_DadosExportados'!$V:$V,$C11,'2_LN_DadosExportados'!$A:$A,"X")+R11)/X11)*$D11,"") -> 0 | F11: =IFERROR(((SUMIFS('2_LN_DadosExportados'!AM:AM,'2_LN_DadosExportados'!$V:$V,$C11,'2_LN_DadosExportados'!$A:$A,"X")+S11)/Y11)*$D11,"") -> 0 | G11: =IFERROR(((SUMIFS('2_LN_DadosExportados'!AN:AN,'2_LN_DadosExportados'!$V:$V,$C11,'2_LN_DadosExportados'!$A:$A,"X")+T11)/Z11)*$D11,"") -> 0 | H11: =IFERROR(((SUMIFS('2_LN_DadosExportados'!AO:AO,'2_LN_DadosExportados'!$V:$V,$C11,'2_LN_DadosExportados'!$A:$A,"X")+U11)/AA11)*$D11,"") -> 0 | I11: =IFERROR(((SUMIFS('2_LN_DadosExportados'!AP:AP,'2_LN_DadosExportados'!$V:$V,$C11,'2_LN_DadosExportados'!$A:$A,"X")+V11)/AB11)*$D11,"") -> 0 | J11: =IFERROR(((SUMIFS('2_LN_DadosExportados'!AQ:AQ,'2_LN_DadosExportados'!$V:$V,$C11,'2_LN_DadosExportados'!$A:$A,"X")+W11)/AC11)*$D11,"") -> 0 | K11: =IFERROR(R11/X11*$D11,"") -> 0 | L11: =IFERROR(S11/Y11*$D11,"") -> 0 | M11: =IFERROR(T11/Z11*$D11,"") -> 0 | N11: =IFERROR(U11/AA11*$D11,"") -> 0 | O11: =IFERROR(V11/AB11*$D11,"") -> 0 | P11: =IFERROR(W11/AC11*$D11,"") -> 0 | Q11: 90 | R11: 0 | S11: 0 | T11: 0 | U11: 0 | V11: 0 | W11: 0 | X11: =AD11*($Q11/100) -> 4348.8 | Y11: =AE11*($Q11/100) -> 4095 | Z11: =AF11*($Q11/100) -> 4336.11 | AA11: =AG11*($Q11/100) -> 4329.27 | AB11: =AH11*($Q11/100) -> 4328.64 | AC11: =AI11*($Q11/100) -> 4367.25 | AD11: 4832 | AE11: 4550 | AF11: 4817.9 | AG11: 4810.3 | AH11: 4809.6 | AI11: 4852.5 | AJ11: 0 | AK11: 0 | AL11: 0 | AM11: 0 | AN11: 0 | AO11: 0 | AP11: =IFERROR(VLOOKUP(C11,'2_LN_DadosExportados'!V:V,1,FALSE),"") | AQ11: {=IF(AND(ISERR(FIND("sim",INDEX('existencia de wc'!K$2:K$193,MATCH('3_Industrial_Plan_Idash'!C11,'existencia de wc'!B$2:B$192,0))))=FALSE,SUMPRODUCT(('2_LN_DadosExportados'!V$2:V$314='3_Industrial_Plan_Idash'!C11)*('2_LN_DadosExportados'!A$2:A$314="X"))>0), "MOSTRAR","")}
